Workbook
Name MPFlight1Total: 'Match Play'!$E$3:$E$6
Name BestBallPointsFifthDefault: Points!$G$9
Name PushPoints: Matches!$B$43
Name ScramblePointsSixth: Points!$L$35:$M$37
Name RedP4: Schedule!$C$28
Name BlueP1: 'Schedule New'!$C$18
Name BestBallPointsEighth: Points!$P$60:$Q$64
Name WhiteP1: Schedule!$C$4
Name RedP2: 'Schedule New'!$C$26
Name RedP5: Schedule!$C$29
Name BestBall: 'Best Ball Scrolf'!$B:$B
Name ScramblePointsThirdDefault: Points!$K$7
Name MatchPlay3_VL: 'Match Play Scrolf 3'!$B:$D
Name BlackP5: Schedule!$C$15
Name BestBallPointsTwelvthDefault: Points!$G$16
Name BestBallPointsFourthDefault: Points!$G$8
Name BlackP3: Schedule!$C$13
Name BlueP1: Schedule!$C$18
Name BestBallPointsSeventh: Points!$N$60:$O$65
Name BlackP2: 'Schedule New'!$C$12
Name ScramblePointsEighth: Points!$P$35:$Q$35
Name BestBallPointsEleventh: Points!$V$60:$W$61
Name MPPointsH: Points!$C$20
Name RedP4: 'Schedule New'!$C$28
Name BestBallPointsThirdDefault: Points!$G$7
Name BestBallPointsEighthDefault: Points!$G$12
Name RedP1: 'Schedule New'!$C$25
Name MPFlight6Total: 'Match Play'!$E$38:$E$41
Name WhiteP6: 'Schedule New'!$C$9
Name ScramblePoints_VL: Points!$B$24:$C$31
Name WhiteP2: Schedule!$C$5
Name ScramblePointsFirstDefault: Points!$K$5
Name ScramblePointsFirst: Points!$B$35:$C$42
Name BestBallPointsEleventhDefault: Points!$G$15
Name ScramblePointsSixthDefault: Points!$K$10
Name MatchPlay2_VL: 'Match Play Scolf 2'!$B:$D
Name ScramblePointsSeventhDefault: Points!$K$11
Name BlueP5: Schedule!$C$22
Name BlackP2: Schedule!$C$12
Name MatchPlay3: 'Match Play Scrolf 3'!$B:$B
Name ScramblePointsFifth: Points!$J$35:$K$38
Name RedP3: Schedule!$C$27
Name BlackP3: 'Schedule New'!$C$13
Name BlueP2: 'Schedule New'!$C$19
Name RedP2: Schedule!$C$26
Name BlueP6: 'Schedule New'!$C$23
Name MPFlight5Total: 'Match Play'!$E$31:$E$34
Name RedP6: 'Schedule New'!$C$30
Name MatchPlayPoints_VL: Points!$B$5:$C$8
Name MPFlight3Total: 'Match Play'!$E$17:$E$20
Name BlueP5: 'Schedule New'!$C$22
Name ScramblePointsFifthDefault: Points!$K$9
Name BestBallPointsNinethDefault: Points!$G$13
Name MPPointsL: Points!$C$21
Name BlueP4: 'Schedule New'!$C$21
Name BlueP2: Schedule!$C$19
Name BestBallPointsSecondDefault: Points!$G$6
Name BestBallPointsSecond: Points!$D$60:$E$70
Name BestBallPointsFirst: Points!$B$60:$C$71
Name Points_BB: Points!$F$5:$G$8

Sheet Ryder Cup Leaderboard
A1: SEMIS MATCH 1
A2: TEAM BAD | B2: =SUM(Matches!D7,Matches!D19, Matches!H7,Matches!H19, ) -> 10
A3: TEAM ROB | B3: =SUM(Matches!F13,Matches!F25, Matches!H13, Matches!H25, ) -> 7
A4: SEMIS MATCH 2
A5: TEAM MITCH | B5: =SUM(Matches!F7,Matches!F19,Matches!H7,Matches!H19, ) -> 7
A6: TEAM AUGUSTA | B6: =SUM(Matches!D13,Matches!D25,Matches!H13,Matches!H25, ) -> 10
A8: FINALS
A9: TBD | B9: =SUM(Matches!D31,Matches!H31) -> 0
A10: TBD | B10: =SUM(Matches!F31,Matches!H31) -> 0
A11: LOSERS
A12: TBD | B12: =SUM(Matches!D37,Matches!H37) -> 0
A13: TBD | B13: =SUM(Matches!F37,Matches!H37) -> 0

Sheet Matches
A2: RYDER CUP SEMIS #1 - TEAM DUTCH VS TEAM ROB
A3: Time | B3: Players | C3: DUTCH WIN | E3: ROB WIN | G3: PUSH
A4: 0.55555556 | B4: Dutch/Sina vs Troy/Dave | D4: =IF(ISBLANK(C4), "0", WinPoints) -> 0 | F4: =IF(ISBLANK(E4), "0", WinPoints) -> 0 | G4: X | H4: =IF(ISBLANK(G4), "0", PushPoints) -> 1
A5: 0.56944444 | B5: Rocky/Kelly vs Rob/Riley | C5: X | D5: =IF(ISBLANK(C5), "0", WinPoints) -> 3 | F5: =IF(ISBLANK(E5), "0", WinPoints) -> 0 | H5: =IF(ISBLANK(G5), "0", PushPoints) -> 0
A6: 0.57638889 | B6: Terby vs Mikey | C6: X | D6: =IF(ISBLANK(C6), "0", WinPoints) -> 3 | F6: =IF(ISBLANK(E6), "0", WinPoints) -> 0 | H6: =IF(ISBLANK(G6), "0", PushPoints) -> 0
D7: =SUM(D4:D6) -> 6 | F7: =SUM(F4:F6) -> 0 | H7: =SUM(H4:H6) -> 1
A8: RYDER CUP SEMIS #1 - TEAM ADAM VS TEAM MITCH
A9: Time | B9: Players | C9: ADAM WIN | E9: MITCH WIN | G9: PUSH
A10: 0.54861111 | B10: Beeler/Beeler vs Miller/Quis | D10: =IF(ISBLANK(C10), "0", WinPoints) -> 0 | F10: =IF(ISBLANK(E10), "0", WinPoints) -> 0 | G10: X | H10: =IF(ISBLANK(G10), "0", PushPoints) -> 1
A11: 0.5625 | B11: Adam/Matt B vs Mitch/Andy | C11: X | D11: =IF(ISBLANK(C11), "0", WinPoints) -> 3 | F11: =IF(ISBLANK(E11), "0", WinPoints) -> 0 | H11: =IF(ISBLANK(G11), "0", PushPoints) -> 0
A12: 0.57638889 | B12: Eric vs Joe | D12: =IF(ISBLANK(C12), "0", WinPoints) -> 0 | E12: X | F12: =IF(ISBLANK(E12), "0", WinPoints) -> 3 | H12: =IF(ISBLANK(G12), "0", PushPoints) -> 0
D13: =SUM(D10:D12) -> 3 | F13: =SUM(F10:F12) -> 3 | H13: =SUM(H10:H12) -> 1
A14: RYDER CUP SEMIS #2 - TEAM DUTCH VS TEAM ROB
A15: Time | B15: Players | C15: DUTCH WIN | E15: ROB WIN | G15: PUSH | H15: PUSH
B16: Dutch/ O'Brien v Boss/tangalakis | D16: =IF(ISBLANK(C16), "0", WinPoints) -> 0 | E16: X | F16: =IF(ISBLANK(E16), "0", WinPoints) -> 3 | H16: =IF(ISBLANK(G16), "0", PushPoints) -> 0
B17: Wiltsey/terbush v line/O'Neil | C17: X | D17: =IF(ISBLANK(C17), "0", WinPoints) -> 3 | F17: =IF(ISBLANK(E17), "0", WinPoints) -> 0 | H17: =IF(ISBLANK(G17), "0", PushPoints) -> 0
B18: Sinacola v d Boucher | D18: =IF(ISBLANK(C18), "0", WinPoints) -> 0 | E18: X | F18: =IF(ISBLANK(E18), "0", WinPoints) -> 3 | H18: =IF(ISBLANK(G18), "0", PushPoints) -> 0
D19: =SUM(D16:D18) -> 3 | F19: =SUM(F16:F18) -> 6 | H19: =SUM(H16:H18) -> 0
A20: RYDER CUP SEMIS #2 - TEAM ADAM VS TEAM MITCH
A21: Time | B21: Players | C21: ADAM WIN | E21: MITCH WIN | G21: PUSH | H21: PUSH
B22: A Beeler v Marcus | C22: X | D22: =IF(ISBLANK(C22), "0", WinPoints) -> 3 | F22: =IF(ISBLANK(E22), "0", WinPoints) -> 0 | H22: =IF(ISBLANK(G22), "0", PushPoints) -> 0
B23: Powell/swiatek v Howell/stetor | C23: X | D23: =IF(ISBLANK(C23), "0", WinPoints) -> 3 | F23: =IF(ISBLANK(E23), "0", WinPoints) -> 0 | H23: =IF(ISBLANK(G23), "0", PushPoints) -> 0
B24: M Boucher/Kyle Beeler v Miller/Savela | D24: =IF(ISBLANK(C24), "0", WinPoints) -> 0 | E24: X | F24: =IF(ISBLANK(E24), "0", WinPoints) -> 3 | H24: =IF(ISBLANK(G24), "0", PushPoints) -> 0
D25: =SUM(D22:D24) -> 6 | F25: =SUM(F22:F24) -> 3 | H25: =SUM(H22:H24) -> 0
A26: RYDER CUP FINALS - TEAM TBD VS TEAM TBD
A27: Time | B27: Players | C27: TBD WIN | E27: TBD WIN | G27: PUSH | H27: PUSH
B28: Swiatek/K Beeler v O'Brien/terbush | D28: =IF(ISBLANK(C28), "0", WinPoints) -> 0 | F28: =IF(ISBLANK(E28), "0", WinPoints) -> 0 | H28: =IF(ISBLANK(G28), "0", PushPoints) -> 0
B29: M Boucher/A Beeler v Wiltsey/sina | D29: =IF(ISBLANK(C29), "0", WinPoints) -> 0 | F29: =IF(ISBLANK(E29), "0", WinPoints) -> 0 | H29: =IF(ISBLANK(G29), "0", PushPoints) -> 0
B30: Powell v Dutch | D30: =IF(ISBLANK(C30), "0", WinPoints) -> 0 | F30: =IF(ISBLANK(E30), "0", WinPoints) -> 0 | H30: =IF(ISBLANK(G30), "0", PushPoints) -> 0
D31: =SUM(D28:D30) -> 0 | F31: =SUM(F28:F30) -> 0 | H31: =SUM(H28:H30) -> 0
A32: RYDER CUP LOSERS - TEAM TBD VS TEAM TBD
A33: Time | B33: Players | C33: TBD WIN | E33: TBD WIN | G33: PUSH | H33: PUSH
B34: Swartz/Savela v Tangalakis/d Boucher | D34: =IF(ISBLANK(C34), "0", WinPoints) -> 0 | F34: =IF(ISBLANK(E34), "0", WinPoints) -> 0 | H34: =IF(ISBLANK(G34), "0", PushPoints) -> 0
B35: Boss/line v Howell/miller | D35: =IF(ISBLANK(C35), "0", WinPoints) -> 0 | F35: =IF(ISBLANK(E35), "0", WinPoints) -> 0 | H35: =IF(ISBLANK(G35), "0", PushPoints) -> 0
B36: O'Neil v Stetor | D36: =IF(ISBLANK(C36), "0", WinPoints) -> 0 | F36: =IF(ISBLANK(E36), "0", WinPoints) -> 0 | H36: =IF(ISBLANK(G36), "0", PushPoints) -> 0
D37: =SUM(D34:D36) -> 0 | F37: =SUM(F34:F36) -> 0 | H37: =SUM(H34:H36) -> 0
B40: Points
A41: Win | B41: 3
A42: Loss | B42: 0
A43: Push | B43: 1

Sheet 3-man Scramble
A1: Match 1
A2: Blue | E2: Black
D3: v
A4: Match 2
A5: Red | E5: White
D6: v
A7: Match 3
A8: White | E8: Black
D9: v
A10: Match 4
A11: Blue | E11: Red
D12: v
A16: SCORING
A17: Team | D17: Points
A18: Black
A19: Blue
A20: Red
A21: White

Sheet Sheet26

Sheet Match Play
A1: FLIGHT 1
A2: Player | B2: M1 | C2: M2 | D2: M3 | E2: Total Points | F2: Flight Finish | G2: Flight Finish | H2: Ryder Cup Points
A3: =WhiteP1 -> Rob (W) | B3: {=If(VLOOKUP(INDEX(MatchPlay1, Match(CONCATENATE("*", WhiteP1, "*"), MatchPlay1, false), 0),MatchPlay1_VL, 2, false) = 0, "TBD", if(VLOOKUP(INDEX(MatchPlay1, Match(CONCATENATE("*", WhiteP1, "*"), MatchPlay1, false), 0),MatchPlay1_VL, 3, false) = "halved", "halved", If(VLOOKUP(INDEX(MatchPlay1, Match(CONCATENATE("*", WhiteP1, "*"), MatchPlay1, false), 0),MatchPlay1_VL, 3, false) <> "AS", if(left(VLOOKUP(INDEX(MatchPlay1, Match(CONCATENATE("*", WhiteP1, "*"), MatchPlay1, false), 0),MatchPlay1_VL, 3, false), 1) = "a", "W", "L"), "TBD")))} -> L | C3: {=If(VLOOKUP(INDEX(MatchPlay2, Match(CONCATENATE("*", WhiteP1, "*"), MatchPlay2, false), 0),MatchPlay2_VL, 2, false) = 0, "TBD", if(VLOOKUP(INDEX(MatchPlay2, Match(CONCATENATE("*", WhiteP1, "*"), MatchPlay2, false), 0),MatchPlay2_VL, 3, false) = "halved", "halved", If(VLOOKUP(INDEX(MatchPlay2, Match(CONCATENATE("*", WhiteP1, "*"), MatchPlay2, false), 0),MatchPlay2_VL, 3, false) <> "AS", if(left(VLOOKUP(INDEX(MatchPlay2, Match(CONCATENATE("*", WhiteP1, "*"), MatchPlay2, false), 0),MatchPlay2_VL, 3, false), 1) = "a", "W", "L"), "TBD")))} -> L | D3: {=If(VLOOKUP(INDEX(MatchPlay3, Match(CONCATENATE("*", WhiteP1, "*"), MatchPlay3, false), 0),MatchPlay3_VL, 2, false) = 0, "TBD", if(VLOOKUP(INDEX(MatchPlay3, Match(CONCATENATE("*", WhiteP1, "*"), MatchPlay3, false), 0),MatchPlay3_VL, 3, false) = "halved", "halved", If(VLOOKUP(INDEX(MatchPlay3, Match(CONCATENATE("*", WhiteP1, "*"), MatchPlay3, false), 0),MatchPlay3_VL, 3, false) <> "AS", if(left(VLOOKUP(INDEX(MatchPlay3, Match(CONCATENATE("*", WhiteP1, "*"), MatchPlay3, false), 0),MatchPlay3_VL, 3, false), 1) = "a", "W", "L"), "TBD")))} -> L | E3: =SUM(IFS(B3="W", MPPointsW, B3="L", MPPointsL, B3="halved", MPPointsH, B3="TBD", "0"), IFS(C3="W", MPPointsW, C3="L", MPPointsL, C3="halved", MPPointsH, C3="TBD", "0"), IFS(D3="W", MPPointsW, D3="L", MPPointsL, D3="halved", MPPointsH, D3="TBD", "0")) -> 0 | F3: =IFS(LARGE(MPFlight1Total, 1)=E3, 1, LARGE(MPFlight1Total, 2)=E3, 2, LARGE(MPFlight1Total, 3)=E3, 3, LARGE(MPFlight1Total, 4)=E3, 4) -> #N/A | G3: =If(C3="TBD", 0, F3) -> #N/A | H3: =If(C3="TBD", 0, VLOOKUP(G3,MatchPlayPoints_VL, 2, false)) -> #N/A
A4: =BlackP1 -> Mitch (A) | B4: {=If(VLOOKUP(INDEX(MatchPlay1, Match(CONCATENATE("*", BlackP1, "*"), MatchPlay1, false), 0),MatchPlay1_VL, 2, false) = 0, "TBD", if(VLOOKUP(INDEX(MatchPlay1, Match(CONCATENATE("*", BlackP1, "*"), MatchPlay1, false), 0),MatchPlay1_VL, 3, false) = "halved", "halved", If(VLOOKUP(INDEX(MatchPlay1, Match(CONCATENATE("*", BlackP1, "*"), MatchPlay1, false), 0),MatchPlay1_VL, 3, false) <> "AS", if(left(VLOOKUP(INDEX(MatchPlay1, Match(CONCATENATE("*", BlackP1, "*"), MatchPlay1, false), 0),MatchPlay1_VL, 3, false), 1) = "b", "W", "L"), "TBD")))} -> #N/A | C4: {=If(VLOOKUP(INDEX(MatchPlay2, Match(CONCATENATE("*", BlackP1, "*"), MatchPlay2, false), 0),MatchPlay2_VL, 2, false) = 0, "TBD", if(VLOOKUP(INDEX(MatchPlay2, Match(CONCATENATE("*", BlackP1, "*"), MatchPlay2, false), 0),MatchPlay2_VL, 3, false) = "halved", "halved", If(VLOOKUP(INDEX(MatchPlay2, Match(CONCATENATE("*", BlackP1, "*"), MatchPlay2, false), 0),MatchPlay2_VL, 3, false) <> "AS", if(left(VLOOKUP(INDEX(MatchPlay2, Match(CONCATENATE("*", BlackP1, "*"), MatchPlay2, false), 0),MatchPlay2_VL, 3, false), 1) = "a", "W", "L"), "TBD")))} -> L | D4: {=If(VLOOKUP(INDEX(MatchPlay3, Match(CONCATENATE("*", BlackP1, "*"), MatchPlay3, false), 0),MatchPlay3_VL, 2, false) = 0, "TBD", if(VLOOKUP(INDEX(MatchPlay3, Match(CONCATENATE("*", BlackP1, "*"), MatchPlay3, false), 0),MatchPlay3_VL, 3, false) = "halved", "halved", If(VLOOKUP(INDEX(MatchPlay3, Match(CONCATENATE("*", BlackP1, "*"), MatchPlay3, false), 0),MatchPlay3_VL, 3, false) <> "AS", if(left(VLOOKUP(INDEX(MatchPlay3, Match(CONCATENATE("*", BlackP1, "*"), MatchPlay3, false), 0),MatchPlay3_VL, 3, false), 1) = "b", "W", "L"), "TBD")))} -> #N/A | E4: =SUM(IFS(B4="W", MPPointsW, B4="L", MPPointsL, B4="halved", MPPointsH, B4="TBD", "0"), IFS(C4="W", MPPointsW, C4="L", MPPointsL, C4="halved", MPPointsH, C4="TBD", "0"), IFS(D4="W", MPPointsW, D4="L", MPPointsL, D4="halved", MPPointsH, D4="TBD", "0")) -> #N/A | F4: =IFS(LARGE(MPFlight1Total, 1)=E4, 1, LARGE(MPFlight1Total, 2)=E4, 2, LARGE(MPFlight1Total, 3)=E4, 3, LARGE(MPFlight1Total, 4)=E4, 4) -> #N/A | G4: 4 | H4: =If(C4="TBD", 0, VLOOKUP(G4,MatchPlayPoints_VL, 2, false)) -> 0
A5: =BlueP1 -> Will (B) | B5: {=If(VLOOKUP(INDEX(MatchPlay1, Match(CONCATENATE("*", BlueP1, "*"), MatchPlay1, false), 0),MatchPlay1_VL, 2, false) = 0, "TBD", if(VLOOKUP(INDEX(MatchPlay1, Match(CONCATENATE("*", BlueP1, "*"), MatchPlay1, false), 0),MatchPlay1_VL, 3, false) = "halved", "halved", If(VLOOKUP(INDEX(MatchPlay1, Match(CONCATENATE("*", BlueP1, "*"), MatchPlay1, false), 0),MatchPlay1_VL, 3, false) <> "AS", if(left(VLOOKUP(INDEX(MatchPlay1, Match(CONCATENATE("*", BlueP1, "*"), MatchPlay1, false), 0),MatchPlay1_VL, 3, false), 1) = "a", "W", "L"), "TBD")))} -> L | C5: {=If(VLOOKUP(INDEX(MatchPlay2, Match(CONCATENATE("*", BlueP1, "*"), MatchPlay2, false), 0),MatchPlay2_VL, 2, false) = 0, "TBD", if(VLOOKUP(INDEX(MatchPlay2, Match(CONCATENATE("*", BlueP1, "*"), MatchPlay2, false), 0),MatchPlay2_VL, 3, false) = "halved", "halved", If(VLOOKUP(INDEX(MatchPlay2, Match(CONCATENATE("*", BlueP1, "*"), MatchPlay2, false), 0),MatchPlay2_VL, 3, false) <> "AS", if(left(VLOOKUP(INDEX(MatchPlay2, Match(CONCATENATE("*", BlueP1, "*"), MatchPlay2, false), 0),MatchPlay2_VL, 3, false), 1) = "b", "W", "L"), "TBD")))} -> #N/A | D5: {=If(VLOOKUP(INDEX(MatchPlay3, Match(CONCATENATE("*", BlueP1, "*"), MatchPlay3, false), 0),MatchPlay3_VL, 2, false) = 0, "TBD", if(VLOOKUP(INDEX(MatchPlay3, Match(CONCATENATE("*", BlueP1, "*"), MatchPlay3, false), 0),MatchPlay3_VL, 3, false) = "halved", "halved", If(VLOOKUP(INDEX(MatchPlay3, Match(CONCATENATE("*", BlueP1, "*"), MatchPlay3, false), 0),MatchPlay3_VL, 3, false) <> "AS", if(left(VLOOKUP(INDEX(MatchPlay3, Match(CONCATENATE("*", BlueP1, "*"), MatchPlay3, false), 0),MatchPlay3_VL, 3, false), 1) = "b", "W", "L"), "TBD")))} -> #N/A | E5: =SUM(IFS(B5="W", MPPointsW, B5="L", MPPointsL, B5="halved", MPPointsH, B5="TBD", "0"), IFS(C5="W", MPPointsW, C5="L", MPPointsL, C5="halved", MPPointsH, C5="TBD", "0"), IFS(D5="W", MPPointsW, D5="L", MPPointsL, D5="halved", MPPointsH, D5="TBD", "0")) -> #N/A | F5: =IFS(LARGE(MPFlight1Total, 1)=E5, 1, LARGE(MPFlight1Total, 2)=E5, 2, LARGE(MPFlight1Total, 3)=E5, 3, LARGE(MPFlight1Total, 4)=E5, 4) -> #N/A | G5: 3 | H5: =If(C5="TBD", 0, VLOOKUP(G5,MatchPlayPoints_VL, 2, false)) -> #N/A
A6: =RedP1 -> Troy (R) | B6: {=If(VLOOKUP(INDEX(MatchPlay1, Match(CONCATENATE("*", RedP1, "*"), MatchPlay1, false), 0),MatchPlay1_VL, 2, false) = 0, "TBD", if(VLOOKUP(INDEX(MatchPlay1, Match(CONCATENATE("*", RedP1, "*"), MatchPlay1, false), 0),MatchPlay1_VL, 3, false) = "halved", "halved", If(VLOOKUP(INDEX(MatchPlay1, Match(CONCATENATE("*", RedP1, "*"), MatchPlay1, false), 0),MatchPlay1_VL, 3, false) <> "AS", if(left(VLOOKUP(INDEX(MatchPlay1, Match(CONCATENATE("*", RedP1, "*"), MatchPlay1, false), 0),MatchPlay1_VL, 3, false), 1) = "b", "W", "L"), "TBD")))} -> #N/A | C6: {=If(VLOOKUP(INDEX(MatchPlay2, Match(CONCATENATE("*", RedP1, "*"), MatchPlay2, false), 0),MatchPlay2_VL, 2, false) = 0, "TBD", if(VLOOKUP(INDEX(MatchPlay2, Match(CONCATENATE("*", RedP1, "*"), MatchPlay2, false), 0),MatchPlay2_VL, 3, false) = "halved", "halved", If(VLOOKUP(INDEX(MatchPlay2, Match(CONCATENATE("*", RedP1, "*"), MatchPlay2, false), 0),MatchPlay2_VL, 3, false) <> "AS", if(left(VLOOKUP(INDEX(MatchPlay2, Match(CONCATENATE("*", RedP1, "*"), MatchPlay2, false), 0),MatchPlay2_VL, 3, false), 1) = "b", "W", "L"), "TBD")))} -> #N/A | D6: {=If(VLOOKUP(INDEX(MatchPlay3, Match(CONCATENATE("*", RedP1, "*"), MatchPlay3, false), 0),MatchPlay3_VL, 2, false) = 0, "TBD", if(VLOOKUP(INDEX(MatchPlay3, Match(CONCATENATE("*", RedP1, "*"), MatchPlay3, false), 0),MatchPlay3_VL, 3, false) = "halved", "halved", If(VLOOKUP(INDEX(MatchPlay3, Match(CONCATENATE("*", RedP1, "*"), MatchPlay3, false), 0),MatchPlay3_VL, 3, false) <> "AS", if(left(VLOOKUP(INDEX(MatchPlay3, Match(CONCATENATE("*", RedP1, "*"), MatchPlay3, false), 0),MatchPlay3_VL, 3, false), 1) = "a", "W", "L"), "TBD")))} -> L | E6: =SUM(IFS(B6="W", MPPointsW, B6="L", MPPointsL, B6="halved", MPPointsH, B6="TBD", "0"), IFS(C6="W", MPPointsW, C6="L", MPPointsL, C6="halved", MPPointsH, C6="TBD", "0"), IFS(D6="W", MPPointsW, D6="L", MPPointsL, D6="halved", MPPointsH, D6="TBD", "0")) -> #N/A | F6: =IFS(LARGE(MPFlight1Total, 1)=E6, 1, LARGE(MPFlight1Total, 2)=E6, 2, LARGE(MPFlight1Total, 3)=E6, 3, LARGE(MPFlight1Total, 4)=E6, 4) -> #N/A | G6: =If(C6="TBD", 0, F6) -> #N/A | H6: =If(C6="TBD", 0, VLOOKUP(G6,MatchPlayPoints_VL, 2, false)) -> #N/A
A8: FLIGHT 2
A9: Player | B9: M1 | C9: M2 | D9: M3 | E9: Total Points | F9: Flight Finish | G9: Flight Finish | H9: Ryder Cup Points
A10: =WhiteP2 -> Dutch (W) | B10: {=If(VLOOKUP(INDEX(MatchPlay1, Match(CONCATENATE("*", WhiteP2, "*"), MatchPlay1, false), 0),MatchPlay1_VL, 2, false) = 0, "TBD", if(VLOOKUP(INDEX(MatchPlay1, Match(CONCATENATE("*", WhiteP2, "*"), MatchPlay1, false), 0),MatchPlay1_VL, 3, false) = "halved", "halved", If(VLOOKUP(INDEX(MatchPlay1, Match(CONCATENATE("*", WhiteP2, "*"), MatchPlay1, false), 0),MatchPlay1_VL, 3, false) <> "AS", if(left(VLOOKUP(INDEX(MatchPlay1, Match(CONCATENATE("*", WhiteP2, "*"), MatchPlay1, false), 0),MatchPlay1_VL, 3, false), 1) = "a", "W", "L"), "TBD")))} -> L | C10: {=If(VLOOKUP(INDEX(MatchPlay2, Match(CONCATENATE("*", WhiteP2, "*"), MatchPlay2, false), 0),MatchPlay2_VL, 2, false) = 0, "TBD", if(VLOOKUP(INDEX(MatchPlay2, Match(CONCATENATE("*", WhiteP2, "*"), MatchPlay2, false), 0),MatchPlay2_VL, 3, false) = "halved", "halved", If(VLOOKUP(INDEX(MatchPlay2, Match(CONCATENATE("*", WhiteP2, "*"), MatchPlay2, false), 0),MatchPlay2_VL, 3, false) <> "AS", if(left(VLOOKUP(INDEX(MatchPlay2, Match(CONCATENATE("*", WhiteP2, "*"), MatchPlay2, false), 0),MatchPlay2_VL, 3, false), 1) = "a", "W", "L"), "TBD")))} -> L | D10: {=If(VLOOKUP(INDEX(MatchPlay3, Match(CONCATENATE("*", WhiteP2, "*"), MatchPlay3, false), 0),MatchPlay3_VL, 2, false) = 0, "TBD", if(VLOOKUP(INDEX(MatchPlay3, Match(CONCATENATE("*", WhiteP2, "*"), MatchPlay3, false), 0),MatchPlay3_VL, 3, false) = "halved", "halved", If(VLOOKUP(INDEX(MatchPlay3, Match(CONCATENATE("*", WhiteP2, "*"), MatchPlay3, false), 0),MatchPlay3_VL, 3, false) <> "AS", if(left(VLOOKUP(INDEX(MatchPlay3, Match(CONCATENATE("*", WhiteP2, "*"), MatchPlay3, false), 0),MatchPlay3_VL, 3, false), 1) = "a", "W", "L"), "TBD")))} -> L | E10: =SUM(IFS(B10="W", MPPointsW, B10="L", MPPointsL, B10="halved", MPPointsH, B10="TBD", "0"), IFS(C10="W", MPPointsW, C10="L", MPPointsL, C10="halved", MPPointsH, C10="TBD", "0"), IFS(D10="W", MPPointsW, D10="L", MPPointsL, D10="halved", MPPointsH, D10="TBD", "0")) -> 0 | F10: =IFS(LARGE(MPFlight2Total, 1)=E10, 1, LARGE(MPFlight2Total, 2)=E10, 2, LARGE(MPFlight2Total, 3)=E10, 3, LARGE(MPFlight2Total, 4)=E10, 4) -> #N/A | G10: =If(C10="TBD", 0, F10) -> #N/A | H10: =If(C10="TBD", 0, VLOOKUP(G10,MatchPlayPoints_VL, 2, false)) -> #N/A
A11: =BlackP2 -> Rocky (A) | B11: {=If(VLOOKUP(INDEX(MatchPlay1, Match(CONCATENATE("*", BlackP2, "*"), MatchPlay1, false), 0),MatchPlay1_VL, 2, false) = 0, "TBD", if(VLOOKUP(INDEX(MatchPlay1, Match(CONCATENATE("*", BlackP2, "*"), MatchPlay1, false), 0),MatchPlay1_VL, 3, false) = "halved", "halved", If(VLOOKUP(INDEX(MatchPlay1, Match(CONCATENATE("*", BlackP2, "*"), MatchPlay1, false), 0),MatchPlay1_VL, 3, false) <> "AS", if(left(VLOOKUP(INDEX(MatchPlay1, Match(CONCATENATE("*", BlackP2, "*"), MatchPlay1, false), 0),MatchPlay1_VL, 3, false), 1) = "a", "W", "L"), "TBD")))} -> L | C11: {=If(VLOOKUP(INDEX(MatchPlay2, Match(CONCATENATE("*", BlackP2, "*"), MatchPlay2, false), 0),MatchPlay2_VL, 2, false) = 0, "TBD", if(VLOOKUP(INDEX(MatchPlay2, Match(CONCATENATE("*", BlackP2, "*"), MatchPlay2, false), 0),MatchPlay2_VL, 3, false) = "halved", "halved", If(VLOOKUP(INDEX(MatchPlay2, Match(CONCATENATE("*", BlackP2, "*"), MatchPlay2, false), 0),MatchPlay2_VL, 3, false) <> "AS", if(left(VLOOKUP(INDEX(MatchPlay2, Match(CONCATENATE("*", BlackP2, "*"), MatchPlay2, false), 0),MatchPlay2_VL, 3, false), 1) = "b", "W", "L"), "TBD")))} -> #N/A | D11: {=If(VLOOKUP(INDEX(MatchPlay3, Match(CONCATENATE("*", BlackP2, "*"), MatchPlay3, false), 0),MatchPlay3_VL, 2, false) = 0, "TBD", if(VLOOKUP(INDEX(MatchPlay3, Match(CONCATENATE("*", BlackP2, "*"), MatchPlay3, false), 0),MatchPlay3_VL, 3, false) = "halved", "halved", If(VLOOKUP(INDEX(MatchPlay3, Match(CONCATENATE("*", BlackP2, "*"), MatchPlay3, false), 0),MatchPlay3_VL, 3, false) <> "AS", if(left(VLOOKUP(INDEX(MatchPlay3, Match(CONCATENATE("*", BlackP2, "*"), MatchPlay3, false), 0),MatchPlay3_VL, 3, false), 1) = "b", "W", "L"), "TBD")))} -> #N/A | E11: =SUM(IFS(B11="W", MPPointsW, B11="L", MPPointsL, B11="halved", MPPointsH, B11="TBD", "0"), IFS(C11="W", MPPointsW, C11="L", MPPointsL, C11="halved", MPPointsH, C11="TBD", "0"), IFS(D11="W", MPPointsW, D11="L", MPPointsL, D11="halved", MPPointsH, D11="TBD", "0")) -> #N/A | F11: =IFS(LARGE(MPFlight2Total, 1)=E11, 1, LARGE(MPFlight2Total, 2)=E11, 2, LARGE(MPFlight2Total, 3)=E11, 3, LARGE(MPFlight2Total, 4)=E11, 4) -> #N/A | G11: =If(C11="TBD", 0, F11) -> #N/A | H11: =If(C11="TBD", 0, VLOOKUP(G11,MatchPlayPoints_VL, 2, false)) -> #N/A
A12: =BlueP2 -> Miller (B) | B12: {=If(VLOOKUP(INDEX(MatchPlay1, Match(CONCATENATE("*", BlueP2, "*"), MatchPlay1, false), 0),MatchPlay1_VL, 2, false) = 0, "TBD", if(VLOOKUP(INDEX(MatchPlay1, Match(CONCATENATE("*", BlueP2, "*"), MatchPlay1, false), 0),MatchPlay1_VL, 3, false) = "halved", "halved", If(VLOOKUP(INDEX(MatchPlay1, Match(CONCATENATE("*", BlueP2, "*"), MatchPlay1, false), 0),MatchPlay1_VL, 3, false) <> "AS", if(left(VLOOKUP(INDEX(MatchPlay1, Match(CONCATENATE("*", BlueP2, "*"), MatchPlay1, false), 0),MatchPlay1_VL, 3, false), 1) = "b", "W", "L"), "TBD")))} -> #N/A | C12: {=If(VLOOKUP(INDEX(MatchPlay2, Match(CONCATENATE("*", BlueP2, "*"), MatchPlay2, false), 0),MatchPlay2_VL, 2, false) = 0, "TBD", if(VLOOKUP(INDEX(MatchPlay2, Match(CONCATENATE("*", BlueP2, "*"), MatchPlay2, false), 0),MatchPlay2_VL, 3, false) = "halved", "halved", If(VLOOKUP(INDEX(MatchPlay2, Match(CONCATENATE("*", BlueP2, "*"), MatchPlay2, false), 0),MatchPlay2_VL, 3, false) <> "AS", if(left(VLOOKUP(INDEX(MatchPlay2, Match(CONCATENATE("*", BlueP2, "*"), MatchPlay2, false), 0),MatchPlay2_VL, 3, false), 1) = "b", "W", "L"), "TBD")))} -> #N/A | D12: {=If(VLOOKUP(INDEX(MatchPlay3, Match(CONCATENATE("*", BlueP2, "*"), MatchPlay3, false), 0),MatchPlay3_VL, 2, false) = 0, "TBD", if(VLOOKUP(INDEX(MatchPlay3, Match(CONCATENATE("*", BlueP2, "*"), MatchPlay3, false), 0),MatchPlay3_VL, 3, false) = "halved", "halved", If(VLOOKUP(INDEX(MatchPlay3, Match(CONCATENATE("*", BlueP2, "*"), MatchPlay3, false), 0),MatchPlay3_VL, 3, false) <> "AS", if(left(VLOOKUP(INDEX(MatchPlay3, Match(CONCATENATE("*", BlueP2, "*"), MatchPlay3, false), 0),MatchPlay3_VL, 3, false), 1) = "a", "W", "L"), "TBD")))} -> L | E12: =SUM(IFS(B12="W", MPPointsW, B12="L", MPPointsL, B12="halved", MPPointsH, B12="TBD", "0"), IFS(C12="W", MPPointsW, C12="L", MPPointsL, C12="halved", MPPointsH, C12="TBD", "0"), IFS(D12="W", MPPointsW, D12="L", MPPointsL, D12="halved", MPPointsH, D12="TBD", "0")) -> #N/A | F12: =IFS(LARGE(MPFlight2Total, 1)=E12, 1, LARGE(MPFlight2Total, 2)=E12, 2, LARGE(MPFlight2Total, 3)=E12, 3, LARGE(MPFlight2Total, 4)=E12, 4) -> #N/A | G12: =If(C12="TBD", 0, F12) -> #N/A | H12: =If(C12="TBD", 0, VLOOKUP(G12,MatchPlayPoints_VL, 2, false)) -> #N/A
A13: =RedP2 -> Ryan (R) | B13: {=If(VLOOKUP(INDEX(MatchPlay1, Match(CONCATENATE("*", RedP2, "*"), MatchPlay1, false), 0),MatchPlay1_VL, 2, false) = 0, "TBD", if(VLOOKUP(INDEX(MatchPlay1, Match(CONCATENATE("*", RedP2, "*"), MatchPlay1, false), 0),MatchPlay1_VL, 3, false) = "halved", "halved", If(VLOOKUP(INDEX(MatchPlay1, Match(CONCATENATE("*", RedP2, "*"), MatchPlay1, false), 0),MatchPlay1_VL, 3, false) <> "AS", if(left(VLOOKUP(INDEX(MatchPlay1, Match(CONCATENATE("*", RedP2, "*"), MatchPlay1, false), 0),MatchPlay1_VL, 3, false), 1) = "b", "W", "L"), "TBD")))} -> #N/A | C13: {=If(VLOOKUP(INDEX(MatchPlay2, Match(CONCATENATE("*", RedP2, "*"), MatchPlay2, false), 0),MatchPlay2_VL, 2, false) = 0, "TBD", if(VLOOKUP(INDEX(MatchPlay2, Match(CONCATENATE("*", RedP2, "*"), MatchPlay2, false), 0),MatchPlay2_VL, 3, false) = "halved", "halved", If(VLOOKUP(INDEX(MatchPlay2, Match(CONCATENATE("*", RedP2, "*"), MatchPlay2, false), 0),MatchPlay2_VL, 3, false) <> "AS", if(left(VLOOKUP(INDEX(MatchPlay2, Match(CONCATENATE("*", RedP2, "*"), MatchPlay2, false), 0),MatchPlay2_VL, 3, false), 1) = "a", "W", "L"), "TBD")))} -> L | D13: {=If(VLOOKUP(INDEX(MatchPlay3, Match(CONCATENATE("*", RedP2, "*"), MatchPlay3, false), 0),MatchPlay3_VL, 2, false) = 0, "TBD", if(VLOOKUP(INDEX(MatchPlay3, Match(CONCATENATE("*", RedP2, "*"), MatchPlay3, false), 0),MatchPlay3_VL, 3, false) = "halved", "halved", If(VLOOKUP(INDEX(MatchPlay3, Match(CONCATENATE("*", RedP2, "*"), MatchPlay3, false), 0),MatchPlay3_VL, 3, false) <> "AS", if(left(VLOOKUP(INDEX(MatchPlay3, Match(CONCATENATE("*", RedP2, "*"), MatchPlay3, false), 0),MatchPlay3_VL, 3, false), 1) = "b", "W", "L"), "TBD")))} -> #N/A | E13: =SUM(IFS(B13="W", MPPointsW, B13="L", MPPointsL, B13="halved", MPPointsH, B13="TBD", "0"), IFS(C13="W", MPPointsW, C13="L", MPPointsL, C13="halved", MPPointsH, C13="TBD", "0"), IFS(D13="W", MPPointsW, D13="L", MPPointsL, D13="halved", MPPointsH, D13="TBD", "0")) -> #N/A | F13: =IFS(LARGE(MPFlight2Total, 1)=E13, 1, LARGE(MPFlight2Total, 2)=E13, 2, LARGE(MPFlight2Total, 3)=E13, 3, LARGE(MPFlight2Total, 4)=E13, 4) -> #N/A | G13: =If(C13="TBD", 0, F13) -> #N/A | H13: =If(C13="TBD", 0, VLOOKUP(G13,MatchPlayPoints_VL, 2, false)) -> #N/A
A15: FLIGHT 3
A16: Player | B16: M1 | C16: M2 | D16: M3 | E16: Total Points | F16: Flight Finish | G16: Flight Finish | H16: Ryder Cup Points
A17: =WhiteP3 -> Adam (W) | B17: {=If(VLOOKUP(INDEX(MatchPlay1, Match(CONCATENATE("*", WhiteP3, "*"), MatchPlay1, false), 0),MatchPlay1_VL, 2, false) = 0, "TBD", if(VLOOKUP(INDEX(MatchPlay1, Match(CONCATENATE("*", WhiteP3, "*"), MatchPlay1, false), 0),MatchPlay1_VL, 3, false) = "halved", "halved", If(VLOOKUP(INDEX(MatchPlay1, Match(CONCATENATE("*", WhiteP3, "*"), MatchPlay1, false), 0),MatchPlay1_VL, 3, false) <> "AS", if(left(VLOOKUP(INDEX(MatchPlay1, Match(CONCATENATE("*", WhiteP3, "*"), MatchPlay1, false), 0),MatchPlay1_VL, 3, false), 1) = "a", "W", "L"), "TBD")))} -> L | C17: {=If(VLOOKUP(INDEX(MatchPlay2, Match(CONCATENATE("*", WhiteP3, "*"), MatchPlay2, false), 0),MatchPlay2_VL, 2, false) = 0, "TBD", if(VLOOKUP(INDEX(MatchPlay2, Match(CONCATENATE("*", WhiteP3, "*"), MatchPlay2, false), 0),MatchPlay2_VL, 3, false) = "halved", "halved", If(VLOOKUP(INDEX(MatchPlay2, Match(CONCATENATE("*", WhiteP3, "*"), MatchPlay2, false), 0),MatchPlay2_VL, 3, false) <> "AS", if(left(VLOOKUP(INDEX(MatchPlay2, Match(CONCATENATE("*", WhiteP3, "*"), MatchPlay2, false), 0),MatchPlay2_VL, 3, false), 1) = "a", "W", "L"), "TBD")))} -> L | D17: {=If(VLOOKUP(INDEX(MatchPlay3, Match(CONCATENATE("*", WhiteP3, "*"), MatchPlay3, false), 0),MatchPlay3_VL, 2, false) = 0, "TBD", if(VLOOKUP(INDEX(MatchPlay3, Match(CONCATENATE("*", WhiteP3, "*"), MatchPlay3, false), 0),MatchPlay3_VL, 3, false) = "halved", "halved", If(VLOOKUP(INDEX(MatchPlay3, Match(CONCATENATE("*", WhiteP3, "*"), MatchPlay3, false), 0),MatchPlay3_VL, 3, false) <> "AS", if(left(VLOOKUP(INDEX(MatchPlay3, Match(CONCATENATE("*", WhiteP3, "*"), MatchPlay3, false), 0),MatchPlay3_VL, 3, false), 1) = "a", "W", "L"), "TBD")))} -> L | E17: =SUM(IFS(B17="W", MPPointsW, B17="L", MPPointsL, B17="halved", MPPointsH, B17="TBD", "0"), IFS(C17="W", MPPointsW, C17="L", MPPointsL, C17="halved", MPPointsH, C17="TBD", "0"), IFS(D17="W", MPPointsW, D17="L", MPPointsL, D17="halved", MPPointsH, D17="TBD", "0")) -> 0 | F17: =IFS(LARGE(MPFlight3Total, 1)=E17, 1, LARGE(MPFlight3Total, 2)=E17, 2, LARGE(MPFlight3Total, 3)=E17, 3, LARGE(MPFlight3Total, 4)=E17, 4) -> #N/A | G17: =If(C17="TBD", 0, F17) -> #N/A | H17: =If(C17="TBD", 0, VLOOKUP(G17,MatchPlayPoints_VL, 2, false)) -> #N/A
A18: =BlackP3 -> Andy (A) | B18: {=If(VLOOKUP(INDEX(MatchPlay1, Match(CONCATENATE("*", BlackP3, "*"), MatchPlay1, false), 0),MatchPlay1_VL, 2, false) = 0, "TBD", if(VLOOKUP(INDEX(MatchPlay1, Match(CONCATENATE("*", BlackP3, "*"), MatchPlay1, false), 0),MatchPlay1_VL, 3, false) = "halved", "halved", If(VLOOKUP(INDEX(MatchPlay1, Match(CONCATENATE("*", BlackP3, "*"), MatchPlay1, false), 0),MatchPlay1_VL, 3, false) <> "AS", if(left(VLOOKUP(INDEX(MatchPlay1, Match(CONCATENATE("*", BlackP3, "*"), MatchPlay1, false), 0),MatchPlay1_VL, 3, false), 1) = "b", "W", "L"), "TBD")))} -> #N/A | C18: {=If(VLOOKUP(INDEX(MatchPlay2, Match(CONCATENATE("*", BlackP3, "*"), MatchPlay2, false), 0),MatchPlay2_VL, 2, false) = 0, "TBD", if(VLOOKUP(INDEX(MatchPlay2, Match(CONCATENATE("*", BlackP3, "*"), MatchPlay2, false), 0),MatchPlay2_VL, 3, false) = "halved", "halved", If(VLOOKUP(INDEX(MatchPlay2, Match(CONCATENATE("*", BlackP3, "*"), MatchPlay2, false), 0),MatchPlay2_VL, 3, false) <> "AS", if(left(VLOOKUP(INDEX(MatchPlay2, Match(CONCATENATE("*", BlackP3, "*"), MatchPlay2, false), 0),MatchPlay2_VL, 3, false), 1) = "b", "W", "L"), "TBD")))} -> #N/A | D18: {=If(VLOOKUP(INDEX(MatchPlay3, Match(CONCATENATE("*", BlackP3, "*"), MatchPlay3, false), 0),MatchPlay3_VL, 2, false) = 0, "TBD", if(VLOOKUP(INDEX(MatchPlay3, Match(CONCATENATE("*", BlackP3, "*"), MatchPlay3, false), 0),MatchPlay3_VL, 3, false) = "halved", "halved", If(VLOOKUP(INDEX(MatchPlay3, Match(CONCATENATE("*", BlackP3, "*"), MatchPlay3, false), 0),MatchPlay3_VL, 3, false) <> "AS", if(left(VLOOKUP(INDEX(MatchPlay3, Match(CONCATENATE("*", BlackP3, "*"), MatchPlay3, false), 0),MatchPlay3_VL, 3, false), 1) = "a", "W", "L"), "TBD")))} -> L | E18: =SUM(IFS(B18="W", MPPointsW, B18="L", MPPointsL, B18="halved", MPPointsH, B18="TBD", "0"), IFS(C18="W", MPPointsW, C18="L", MPPointsL, C18="halved", MPPointsH, C18="TBD", "0"), IFS(D18="W", MPPointsW, D18="L", MPPointsL, D18="halved", MPPointsH, D18="TBD", "0")) -> #N/A | F18: =IFS(LARGE(MPFlight3Total, 1)=E18, 1, LARGE(MPFlight3Total, 2)=E18, 2, LARGE(MPFlight3Total, 3)=E18, 3, LARGE(MPFlight3Total, 4)=E18, 4) -> #N/A | G18: =If(C18="TBD", 0, F18) -> #N/A | H18: =If(C18="TBD", 0, VLOOKUP(G18,MatchPlayPoints_VL, 2, false)) -> #N/A
A19: =BlueP3 -> Joe (B) | B19: {=If(VLOOKUP(INDEX(MatchPlay1, Match(CONCATENATE("*", BlueP3, "*"), MatchPlay1, false), 0),MatchPlay1_VL, 2, false) = 0, "TBD", if(VLOOKUP(INDEX(MatchPlay1, Match(CONCATENATE("*", BlueP3, "*"), MatchPlay1, false), 0),MatchPlay1_VL, 3, false) = "halved", "halved", If(VLOOKUP(INDEX(MatchPlay1, Match(CONCATENATE("*", BlueP3, "*"), MatchPlay1, false), 0),MatchPlay1_VL, 3, false) <> "AS", if(left(VLOOKUP(INDEX(MatchPlay1, Match(CONCATENATE("*", BlueP3, "*"), MatchPlay1, false), 0),MatchPlay1_VL, 3, false), 1) = "b", "W", "L"), "TBD")))} -> #N/A | C19: {=If(VLOOKUP(INDEX(MatchPlay2, Match(CONCATENATE("*", BlueP3, "*"), MatchPlay2, false), 0),MatchPlay2_VL, 2, false) = 0, "TBD", if(VLOOKUP(INDEX(MatchPlay2, Match(CONCATENATE("*", BlueP3, "*"), MatchPlay2, false), 0),MatchPlay2_VL, 3, false) = "halved", "halved", If(VLOOKUP(INDEX(MatchPlay2, Match(CONCATENATE("*", BlueP3, "*"), MatchPlay2, false), 0),MatchPlay2_VL, 3, false) <> "AS", if(left(VLOOKUP(INDEX(MatchPlay2, Match(CONCATENATE("*", BlueP3, "*"), MatchPlay2, false), 0),MatchPlay2_VL, 3, false), 1) = "a", "W", "L"), "TBD")))} -> L | D19: {=If(VLOOKUP(INDEX(MatchPlay3, Match(CONCATENATE("*", BlueP3, "*"), MatchPlay3, false), 0),MatchPlay3_VL, 2, false) = 0, "TBD", if(VLOOKUP(INDEX(MatchPlay3, Match(CONCATENATE("*", BlueP3, "*"), MatchPlay3, false), 0),MatchPlay3_VL, 3, false) = "halved", "halved", If(VLOOKUP(INDEX(MatchPlay3, Match(CONCATENATE("*", BlueP3, "*"), MatchPlay3, false), 0),MatchPlay3_VL, 3, false) <> "AS", if(left(VLOOKUP(INDEX(MatchPlay3, Match(CONCATENATE("*", BlueP3, "*"), MatchPlay3, false), 0),MatchPlay3_VL, 3, false), 1) = "b", "W", "L"), "TBD")))} -> #N/A | E19: =SUM(IFS(B19="W", MPPointsW, B19="L", MPPointsL, B19="halved", MPPointsH, B19="TBD", "0"), IFS(C19="W", MPPointsW, C19="L", MPPointsL, C19="halved", MPPointsH, C19="TBD", "0"), IFS(D19="W", MPPointsW, D19="L", MPPointsL, D19="halved", MPPointsH, D19="TBD", "0")) -> #N/A | F19: =IFS(LARGE(MPFlight3Total, 1)=E19, 1, LARGE(MPFlight3Total, 2)=E19, 2, LARGE(MPFlight3Total, 3)=E19, 3, LARGE(MPFlight3Total, 4)=E19, 4) -> #N/A | G19: =If(C19="TBD", 0, F19) -> #N/A | H19: =If(C19="TBD", 0, VLOOKUP(G19,MatchPlayPoints_VL, 2, false)) -> #N/A
A20: =RedP3 -> Tyler (R) | B20: {=If(VLOOKUP(INDEX(MatchPlay1, Match(CONCATENATE("*", RedP3, "*"), MatchPlay1, false), 0),MatchPlay1_VL, 2, false) = 0, "TBD", if(VLOOKUP(INDEX(MatchPlay1, Match(CONCATENATE("*", RedP3, "*"), MatchPlay1, false), 0),MatchPlay1_VL, 3, false) = "halved", "halved", If(VLOOKUP(INDEX(MatchPlay1, Match(CONCATENATE("*", RedP3, "*"), MatchPlay1, false), 0),MatchPlay1_VL, 3, false) <> "AS", if(left(VLOOKUP(INDEX(MatchPlay1, Match(CONCATENATE("*", RedP3, "*"), MatchPlay1, false), 0),MatchPlay1_VL, 3, false), 1) = "a", "W", "L"), "TBD")))} -> L | C20: {=If(VLOOKUP(INDEX(MatchPlay2, Match(CONCATENATE("*", RedP3, "*"), MatchPlay2, false), 0),MatchPlay2_VL, 2, false) = 0, "TBD", if(VLOOKUP(INDEX(MatchPlay2, Match(CONCATENATE("*", RedP3, "*"), MatchPlay2, false), 0),MatchPlay2_VL, 3, false) = "halved", "halved", If(VLOOKUP(INDEX(MatchPlay2, Match(CONCATENATE("*", RedP3, "*"), MatchPlay2, false), 0),MatchPlay2_VL, 3, false) <> "AS", if(left(VLOOKUP(INDEX(MatchPlay2, Match(CONCATENATE("*", RedP3, "*"), MatchPlay2, false), 0),MatchPlay2_VL, 3, false), 1) = "b", "W", "L"), "TBD")))} -> #N/A | D20: {=If(VLOOKUP(INDEX(MatchPlay3, Match(CONCATENATE("*", RedP3, "*"), MatchPlay3, false), 0),MatchPlay3_VL, 2, false) = 0, "TBD", if(VLOOKUP(INDEX(MatchPlay3, Match(CONCATENATE("*", RedP3, "*"), MatchPlay3, false), 0),MatchPlay3_VL, 3, false) = "halved", "halved", If(VLOOKUP(INDEX(MatchPlay3, Match(CONCATENATE("*", RedP3, "*"), MatchPlay3, false), 0),MatchPlay3_VL, 3, false) <> "AS", if(left(VLOOKUP(INDEX(MatchPlay3, Match(CONCATENATE("*", RedP3, "*"), MatchPlay3, false), 0),MatchPlay3_VL, 3, false), 1) = "b", "W", "L"), "TBD")))} -> #N/A | E20: =SUM(IFS(B20="W", MPPointsW, B20="L", MPPointsL, B20="halved", MPPointsH, B20="TBD", "0"), IFS(C20="W", MPPointsW, C20="L", MPPointsL, C20="halved", MPPointsH, C20="TBD", "0"), IFS(D20="W", MPPointsW, D20="L", MPPointsL, D20="halved", MPPointsH, D20="TBD", "0")) -> #N/A | F20: =IFS(LARGE(MPFlight3Total, 1)=E20, 1, LARGE(MPFlight3Total, 2)=E20, 2, LARGE(MPFlight3Total, 3)=E20, 3, LARGE(MPFlight3Total, 4)=E20, 4) -> #N/A | G20: =If(C20="TBD", 0, F20) -> #N/A | H20: =If(C20="TBD", 0, VLOOKUP(G20,MatchPlayPoints_VL, 2, false)) -> #N/A
A22: FLIGHT 4
A23: Player | B23: M1 | C23: M2 | D23: M3 | E23: Total Points | F23: Flight Finish | G23: Flight Finish | H23: Ryder Cup Points
A24: =WhiteP4 -> Chad (W) | B24: {=If(VLOOKUP(INDEX(MatchPlay1, Match(CONCATENATE("*", WhiteP4, "*"), MatchPlay1, false), 0),MatchPlay1_VL, 2, false) = 0, "TBD", if(VLOOKUP(INDEX(MatchPlay1, Match(CONCATENATE("*", WhiteP4, "*"), MatchPlay1, false), 0),MatchPlay1_VL, 3, false) = "halved", "halved", If(VLOOKUP(INDEX(MatchPlay1, Match(CONCATENATE("*", WhiteP4, "*"), MatchPlay1, false), 0),MatchPlay1_VL, 3, false) <> "AS", if(left(VLOOKUP(INDEX(MatchPlay1, Match(CONCATENATE("*", WhiteP4, "*"), MatchPlay1, false), 0),MatchPlay1_VL, 3, false), 1) = "a", "W", "L"), "TBD")))} -> L | C24: {=If(VLOOKUP(INDEX(MatchPlay2, Match(CONCATENATE("*", WhiteP4, "*"), MatchPlay2, false), 0),MatchPlay2_VL, 2, false) = 0, "TBD", if(VLOOKUP(INDEX(MatchPlay2, Match(CONCATENATE("*", WhiteP4, "*"), MatchPlay2, false), 0),MatchPlay2_VL, 3, false) = "halved", "halved", If(VLOOKUP(INDEX(MatchPlay2, Match(CONCATENATE("*", WhiteP4, "*"), MatchPlay2, false), 0),MatchPlay2_VL, 3, false) <> "AS", if(left(VLOOKUP(INDEX(MatchPlay2, Match(CONCATENATE("*", WhiteP4, "*"), MatchPlay2, false), 0),MatchPlay2_VL, 3, false), 1) = "a", "W", "L"), "TBD")))} -> L | D24: {=If(VLOOKUP(INDEX(MatchPlay3, Match(CONCATENATE("*", WhiteP4, "*"), MatchPlay3, false), 0),MatchPlay3_VL, 2, false) = 0, "TBD", if(VLOOKUP(INDEX(MatchPlay3, Match(CONCATENATE("*", WhiteP4, "*"), MatchPlay3, false), 0),MatchPlay3_VL, 3, false) = "halved", "halved", If(VLOOKUP(INDEX(MatchPlay3, Match(CONCATENATE("*", WhiteP4, "*"), MatchPlay3, false), 0),MatchPlay3_VL, 3, false) <> "AS", if(left(VLOOKUP(INDEX(MatchPlay3, Match(CONCATENATE("*", WhiteP4, "*"), MatchPlay3, false), 0),MatchPlay3_VL, 3, false), 1) = "a", "W", "L"), "TBD")))} -> L | E24: =SUM(IFS(B24="W", MPPointsW, B24="L", MPPointsL, B24="halved", MPPointsH, B24="TBD", "0"), IFS(C24="W", MPPointsW, C24="L", MPPointsL, C24="halved", MPPointsH, C24="TBD", "0"), IFS(D24="W", MPPointsW, D24="L", MPPointsL, D24="halved", MPPointsH, D24="TBD", "0")) -> 0 | F24: =IFS(LARGE(MPFlight4Total, 1)=E24, 1, LARGE(MPFlight4Total, 2)=E24, 2, LARGE(MPFlight4Total, 3)=E24, 3, LARGE(MPFlight4Total, 4)=E24, 4) -> #N/A | G24: 3 | H24: =If(C24="TBD", 0, VLOOKUP(G24,MatchPlayPoints_VL, 2, false)) -> 0.5
A25: =BlackP4 -> Paul (A) | B25: {=If(VLOOKUP(INDEX(MatchPlay1, Match(CONCATENATE("*", BlackP4, "*"), MatchPlay1, false), 0),MatchPlay1_VL, 2, false) = 0, "TBD", if(VLOOKUP(INDEX(MatchPlay1, Match(CONCATENATE("*", BlackP4, "*"), MatchPlay1, false), 0),MatchPlay1_VL, 3, false) = "halved", "halved", If(VLOOKUP(INDEX(MatchPlay1, Match(CONCATENATE("*", BlackP4, "*"), MatchPlay1, false), 0),MatchPlay1_VL, 3, false) <> "AS", if(left(VLOOKUP(INDEX(MatchPlay1, Match(CONCATENATE("*", BlackP4, "*"), MatchPlay1, false), 0),MatchPlay1_VL, 3, false), 1) = "b", "W", "L"), "TBD")))} -> #N/A | C25: {=If(VLOOKUP(INDEX(MatchPlay2, Match(CONCATENATE("*", BlackP4, "*"), MatchPlay2, false), 0),MatchPlay2_VL, 2, false) = 0, "TBD", if(VLOOKUP(INDEX(MatchPlay2, Match(CONCATENATE("*", BlackP4, "*"), MatchPlay2, false), 0),MatchPlay2_VL, 3, false) = "halved", "halved", If(VLOOKUP(INDEX(MatchPlay2, Match(CONCATENATE("*", BlackP4, "*"), MatchPlay2, false), 0),MatchPlay2_VL, 3, false) <> "AS", if(left(VLOOKUP(INDEX(MatchPlay2, Match(CONCATENATE("*", BlackP4, "*"), MatchPlay2, false), 0),MatchPlay2_VL, 3, false), 1) = "a", "W", "L"), "TBD")))} -> L | D25: {=If(VLOOKUP(INDEX(MatchPlay3, Match(CONCATENATE("*", BlackP4, "*"), MatchPlay3, false), 0),MatchPlay3_VL, 2, false) = 0, "TBD", if(VLOOKUP(INDEX(MatchPlay3, Match(CONCATENATE("*", BlackP4, "*"), MatchPlay3, false), 0),MatchPlay3_VL, 3, false) = "halved", "halved", If(VLOOKUP(INDEX(MatchPlay3, Match(CONCATENATE("*", BlackP4, "*"), MatchPlay3, false), 0),MatchPlay3_VL, 3, false) <> "AS", if(left(VLOOKUP(INDEX(MatchPlay3, Match(CONCATENATE("*", BlackP4, "*"), MatchPlay3, false), 0),MatchPlay3_VL, 3, false), 1) = "b", "W", "L"), "TBD")))} -> #N/A | E25: =SUM(IFS(B25="W", MPPointsW, B25="L", MPPointsL, B25="halved", MPPointsH, B25="TBD", "0"), IFS(C25="W", MPPointsW, C25="L", MPPointsL, C25="halved", MPPointsH, C25="TBD", "0"), IFS(D25="W", MPPointsW, D25="L", MPPointsL, D25="halved", MPPointsH, D25="TBD", "0")) -> #N/A | F25: =IFS(LARGE(MPFlight4Total, 1)=E25, 1, LARGE(MPFlight4Total, 2)=E25, 2, LARGE(MPFlight4Total, 3)=E25, 3, LARGE(MPFlight4Total, 4)=E25, 4) -> #N/A | G25: =If(C25="TBD", 0, F25) -> #N/A | H25: =If(C25="TBD", 0, VLOOKUP(G25,MatchPlayPoints_VL, 2, false)) -> #N/A
A26: =BlueP4 -> Kelly (B) | B26: {=If(VLOOKUP(INDEX(MatchPlay1, Match(CONCATENATE("*", BlueP4, "*"), MatchPlay1, false), 0),MatchPlay1_VL, 2, false) = 0, "TBD", if(VLOOKUP(INDEX(MatchPlay1, Match(CONCATENATE("*", BlueP4, "*"), MatchPlay1, false), 0),MatchPlay1_VL, 3, false) = "halved", "halved", If(VLOOKUP(INDEX(MatchPlay1, Match(CONCATENATE("*", BlueP4, "*"), MatchPlay1, false), 0),MatchPlay1_VL, 3, false) <> "AS", if(left(VLOOKUP(INDEX(MatchPlay1, Match(CONCATENATE("*", BlueP4, "*"), MatchPlay1, false), 0),MatchPlay1_VL, 3, false), 1) = "a", "W", "L"), "TBD")))} -> L | C26: {=If(VLOOKUP(INDEX(MatchPlay2, Match(CONCATENATE("*", BlueP4, "*"), MatchPlay2, false), 0),MatchPlay2_VL, 2, false) = 0, "TBD", if(VLOOKUP(INDEX(MatchPlay2, Match(CONCATENATE("*", BlueP4, "*"), MatchPlay2, false), 0),MatchPlay2_VL, 3, false) = "halved", "halved", If(VLOOKUP(INDEX(MatchPlay2, Match(CONCATENATE("*", BlueP4, "*"), MatchPlay2, false), 0),MatchPlay2_VL, 3, false) <> "AS", if(left(VLOOKUP(INDEX(MatchPlay2, Match(CONCATENATE("*", BlueP4, "*"), MatchPlay2, false), 0),MatchPlay2_VL, 3, false), 1) = "b", "W", "L"), "TBD")))} -> #N/A | D26: {=If(VLOOKUP(INDEX(MatchPlay3, Match(CONCATENATE("*", BlueP4, "*"), MatchPlay3, false), 0),MatchPlay3_VL, 2, false) = 0, "TBD", if(VLOOKUP(INDEX(MatchPlay3, Match(CONCATENATE("*", BlueP4, "*"), MatchPlay3, false), 0),MatchPlay3_VL, 3, false) = "halved", "halved", If(VLOOKUP(INDEX(MatchPlay3, Match(CONCATENATE("*", BlueP4, "*"), MatchPlay3, false), 0),MatchPlay3_VL, 3, false) <> "AS", if(left(VLOOKUP(INDEX(MatchPlay3, Match(CONCATENATE("*", BlueP4, "*"), MatchPlay3, false), 0),MatchPlay3_VL, 3, false), 1) = "b", "W", "L"), "TBD")))} -> #N/A | E26: =SUM(IFS(B26="W", MPPointsW, B26="L", MPPointsL, B26="halved", MPPointsH, B26="TBD", "0"), IFS(C26="W", MPPointsW, C26="L", MPPointsL, C26="halved", MPPointsH, C26="TBD", "0"), IFS(D26="W", MPPointsW, D26="L", MPPointsL, D26="halved", MPPointsH, D26="TBD", "0")) -> #N/A | F26: =IFS(LARGE(MPFlight4Total, 1)=E26, 1, LARGE(MPFlight4Total, 2)=E26, 2, LARGE(MPFlight4Total, 3)=E26, 3, LARGE(MPFlight4Total, 4)=E26, 4) -> #N/A | G26: 2 | H26: =If(C26="TBD", 0, VLOOKUP(G26,MatchPlayPoints_VL, 2, false)) -> #N/A
A27: =RedP4 -> Riley (R) | B27: {=If(VLOOKUP(INDEX(MatchPlay1, Match(CONCATENATE("*", RedP4, "*"), MatchPlay1, false), 0),MatchPlay1_VL, 2, false) = 0, "TBD", if(VLOOKUP(INDEX(MatchPlay1, Match(CONCATENATE("*", RedP4, "*"), MatchPlay1, false), 0),MatchPlay1_VL, 3, false) = "halved", "halved", If(VLOOKUP(INDEX(MatchPlay1, Match(CONCATENATE("*", RedP4, "*"), MatchPlay1, false), 0),MatchPlay1_VL, 3, false) <> "AS", if(left(VLOOKUP(INDEX(MatchPlay1, Match(CONCATENATE("*", RedP4, "*"), MatchPlay1, false), 0),MatchPlay1_VL, 3, false), 1) = "b", "W", "L"), "TBD")))} -> #N/A | C27: {=If(VLOOKUP(INDEX(MatchPlay2, Match(CONCATENATE("*", RedP4, "*"), MatchPlay2, false), 0),MatchPlay2_VL, 2, false) = 0, "TBD", if(VLOOKUP(INDEX(MatchPlay2, Match(CONCATENATE("*", RedP4, "*"), MatchPlay2, false), 0),MatchPlay2_VL, 3, false) = "halved", "halved", If(VLOOKUP(INDEX(MatchPlay2, Match(CONCATENATE("*", RedP4, "*"), MatchPlay2, false), 0),MatchPlay2_VL, 3, false) <> "AS", if(left(VLOOKUP(INDEX(MatchPlay2, Match(CONCATENATE("*", RedP4, "*"), MatchPlay2, false), 0),MatchPlay2_VL, 3, false), 1) = "b", "W", "L"), "TBD")))} -> #N/A | D27: {=If(VLOOKUP(INDEX(MatchPlay3, Match(CONCATENATE("*", RedP4, "*"), MatchPlay3, false), 0),MatchPlay3_VL, 2, false) = 0, "TBD", if(VLOOKUP(INDEX(MatchPlay3, Match(CONCATENATE("*", RedP4, "*"), MatchPlay3, false), 0),MatchPlay3_VL, 3, false) = "halved", "halved", If(VLOOKUP(INDEX(MatchPlay3, Match(CONCATENATE("*", RedP4, "*"), MatchPlay3, false), 0),MatchPlay3_VL, 3, false) <> "AS", if(left(VLOOKUP(INDEX(MatchPlay3, Match(CONCATENATE("*", RedP4, "*"), MatchPlay3, false), 0),MatchPlay3_VL, 3, false), 1) = "a", "W", "L"), "TBD")))} -> L | E27: =SUM(IFS(B27="W", MPPointsW, B27="L", MPPointsL, B27="halved", MPPointsH, B27="TBD", "0"), IFS(C27="W", MPPointsW, C27="L", MPPointsL, C27="halved", MPPointsH, C27="TBD", "0"), IFS(D27="W", MPPointsW, D27="L", MPPointsL, D27="halved", MPPointsH, D27="TBD", "0")) -> #N/A | F27: =IFS(LARGE(MPFlight4Total, 1)=E27, 1, LARGE(MPFlight4Total, 2)=E27, 2, LARGE(MPFlight4Total, 3)=E27, 3, LARGE(MPFlight4Total, 4)=E27, 4) -> #N/A | G27: =If(C27="TBD", 0, F27) -> #N/A | H27: =If(C27="TBD", 0, VLOOKUP(G27,MatchPlayPoints_VL, 2, false)) -> #N/A
A29: FLIGHT 5
A30: Player | B30: M1 | C30: M2 | D30: M3 | E30: Total Points | F30: Flight Finish | G30: Flight Finish | H30: Ryder Cup Points
A31: =WhiteP5 -> Marcus (W) | B31: {=If(VLOOKUP(INDEX(MatchPlay1, Match(CONCATENATE("*", WhiteP5, "*"), MatchPlay1, false), 0),MatchPlay1_VL, 2, false) = 0, "TBD", if(VLOOKUP(INDEX(MatchPlay1, Match(CONCATENATE("*", WhiteP5, "*"), MatchPlay1, false), 0),MatchPlay1_VL, 3, false) = "halved", "halved", If(VLOOKUP(INDEX(MatchPlay1, Match(CONCATENATE("*", WhiteP5, "*"), MatchPlay1, false), 0),MatchPlay1_VL, 3, false) <> "AS", if(left(VLOOKUP(INDEX(MatchPlay1, Match(CONCATENATE("*", WhiteP5, "*"), MatchPlay1, false), 0),MatchPlay1_VL, 3, false), 1) = "a", "W", "L"), "TBD")))} -> L | C31: {=If(VLOOKUP(INDEX(MatchPlay2, Match(CONCATENATE("*", WhiteP5, "*"), MatchPlay2, false), 0),MatchPlay2_VL, 2, false) = 0, "TBD", if(VLOOKUP(INDEX(MatchPlay2, Match(CONCATENATE("*", WhiteP5, "*"), MatchPlay2, false), 0),MatchPlay2_VL, 3, false) = "halved", "halved", If(VLOOKUP(INDEX(MatchPlay2, Match(CONCATENATE("*", WhiteP5, "*"), MatchPlay2, false), 0),MatchPlay2_VL, 3, false) <> "AS", if(left(VLOOKUP(INDEX(MatchPlay2, Match(CONCATENATE("*", WhiteP5, "*"), MatchPlay2, false), 0),MatchPlay2_VL, 3, false), 1) = "a", "W", "L"), "TBD")))} -> L | D31: {=If(VLOOKUP(INDEX(MatchPlay3, Match(CONCATENATE("*", WhiteP5, "*"), MatchPlay3, false), 0),MatchPlay3_VL, 2, false) = 0, "TBD", if(VLOOKUP(INDEX(MatchPlay3, Match(CONCATENATE("*", WhiteP5, "*"), MatchPlay3, false), 0),MatchPlay3_VL, 3, false) = "halved", "halved", If(VLOOKUP(INDEX(MatchPlay3, Match(CONCATENATE("*", WhiteP5, "*"), MatchPlay3, false), 0),MatchPlay3_VL, 3, false) <> "AS", if(left(VLOOKUP(INDEX(MatchPlay3, Match(CONCATENATE("*", WhiteP5, "*"), MatchPlay3, false), 0),MatchPlay3_VL, 3, false), 1) = "a", "W", "L"), "TBD")))} -> L | E31: =SUM(IFS(B31="W", MPPointsW, B31="L", MPPointsL, B31="halved", MPPointsH, B31="TBD", "0"), IFS(C31="W", MPPointsW, C31="L", MPPointsL, C31="halved", MPPointsH, C31="TBD", "0"), IFS(D31="W", MPPointsW, D31="L", MPPointsL, D31="halved", MPPointsH, D31="TBD", "0")) -> 0 | F31: =IFS(LARGE(MPFlight5Total, 1)=E31, 1, LARGE(MPFlight5Total, 2)=E31, 2, LARGE(MPFlight5Total, 3)=E31, 3, LARGE(MPFlight5Total, 4)=E31, 4) -> #N/A | G31: =If(C31="TBD", 0, F31) -> #N/A | H31: =If(C31="TBD", 0, VLOOKUP(G31,MatchPlayPoints_VL, 2, false)) -> #N/A
A32: =BlackP5 -> Andrew (A) | B32: {=If(VLOOKUP(INDEX(MatchPlay1, Match(CONCATENATE("*", BlackP5, "*"), MatchPlay1, false), 0),MatchPlay1_VL, 2, false) = 0, "TBD", if(VLOOKUP(INDEX(MatchPlay1, Match(CONCATENATE("*", BlackP5, "*"), MatchPlay1, false), 0),MatchPlay1_VL, 3, false) = "halved", "halved", If(VLOOKUP(INDEX(MatchPlay1, Match(CONCATENATE("*", BlackP5, "*"), MatchPlay1, false), 0),MatchPlay1_VL, 3, false) <> "AS", if(left(VLOOKUP(INDEX(MatchPlay1, Match(CONCATENATE("*", BlackP5, "*"), MatchPlay1, false), 0),MatchPlay1_VL, 3, false), 1) = "a", "W", "L"), "TBD")))} -> L | C32: {=If(VLOOKUP(INDEX(MatchPlay2, Match(CONCATENATE("*", BlackP5, "*"), MatchPlay2, false), 0),MatchPlay2_VL, 2, false) = 0, "TBD", if(VLOOKUP(INDEX(MatchPlay2, Match(CONCATENATE("*", BlackP5, "*"), MatchPlay2, false), 0),MatchPlay2_VL, 3, false) = "halved", "halved", If(VLOOKUP(INDEX(MatchPlay2, Match(CONCATENATE("*", BlackP5, "*"), MatchPlay2, false), 0),MatchPlay2_VL, 3, false) <> "AS", if(left(VLOOKUP(INDEX(MatchPlay2, Match(CONCATENATE("*", BlackP5, "*"), MatchPlay2, false), 0),MatchPlay2_VL, 3, false), 1) = "b", "W", "L"), "TBD")))} -> #N/A | D32: {=If(VLOOKUP(INDEX(MatchPlay3, Match(CONCATENATE("*", BlackP5, "*"), MatchPlay3, false), 0),MatchPlay3_VL, 2, false) = 0, "TBD", if(VLOOKUP(INDEX(MatchPlay3, Match(CONCATENATE("*", BlackP5, "*"), MatchPlay3, false), 0),MatchPlay3_VL, 3, false) = "halved", "halved", If(VLOOKUP(INDEX(MatchPlay3, Match(CONCATENATE("*", BlackP5, "*"), MatchPlay3, false), 0),MatchPlay3_VL, 3, false) <> "AS", if(left(VLOOKUP(INDEX(MatchPlay3, Match(CONCATENATE("*", BlackP5, "*"), MatchPlay3, false), 0),MatchPlay3_VL, 3, false), 1) = "b", "W", "L"), "TBD")))} -> #N/A | E32: =SUM(IFS(B32="W", MPPointsW, B32="L", MPPointsL, B32="halved", MPPointsH, B32="TBD", "0"), IFS(C32="W", MPPointsW, C32="L", MPPointsL, C32="halved", MPPointsH, C32="TBD", "0"), IFS(D32="W", MPPointsW, D32="L", MPPointsL, D32="halved", MPPointsH, D32="TBD", "0")) -> #N/A | F32: =IFS(LARGE(MPFlight5Total, 1)=E32, 1, LARGE(MPFlight5Total, 2)=E32, 2, LARGE(MPFlight5Total, 3)=E32, 3, LARGE(MPFlight5Total, 4)=E32, 4) -> #N/A | G32: 3 | H32: =If(C32="TBD", 0, VLOOKUP(G32,MatchPlayPoints_VL, 2, false)) -> #N/A
A33: =BlueP5 -> Mikey (B) | B33: {=If(VLOOKUP(INDEX(MatchPlay1, Match(CONCATENATE("*", BlueP5, "*"), MatchPlay1, false), 0),MatchPlay1_VL, 2, false) = 0, "TBD", if(VLOOKUP(INDEX(MatchPlay1, Match(CONCATENATE("*", BlueP5, "*"), MatchPlay1, false), 0),MatchPlay1_VL, 3, false) = "halved", "halved", If(VLOOKUP(INDEX(MatchPlay1, Match(CONCATENATE("*", BlueP5, "*"), MatchPlay1, false), 0),MatchPlay1_VL, 3, false) <> "AS", if(left(VLOOKUP(INDEX(MatchPlay1, Match(CONCATENATE("*", BlueP5, "*"), MatchPlay1, false), 0),MatchPlay1_VL, 3, false), 1) = "b", "W", "L"), "TBD")))} -> #N/A | C33: {=If(VLOOKUP(INDEX(MatchPlay2, Match(CONCATENATE("*", BlueP5, "*"), MatchPlay2, false), 0),MatchPlay2_VL, 2, false) = 0, "TBD", if(VLOOKUP(INDEX(MatchPlay2, Match(CONCATENATE("*", BlueP5, "*"), MatchPlay2, false), 0),MatchPlay2_VL, 3, false) = "halved", "halved", If(VLOOKUP(INDEX(MatchPlay2, Match(CONCATENATE("*", BlueP5, "*"), MatchPlay2, false), 0),MatchPlay2_VL, 3, false) <> "AS", if(left(VLOOKUP(INDEX(MatchPlay2, Match(CONCATENATE("*", BlueP5, "*"), MatchPlay2, false), 0),MatchPlay2_VL, 3, false), 1) = "b", "W", "L"), "TBD")))} -> #N/A | D33: {=If(VLOOKUP(INDEX(MatchPlay3, Match(CONCATENATE("*", BlueP5, "*"), MatchPlay3, false), 0),MatchPlay3_VL, 2, false) = 0, "TBD", if(VLOOKUP(INDEX(MatchPlay3, Match(CONCATENATE("*", BlueP5, "*"), MatchPlay3, false), 0),MatchPlay3_VL, 3, false) = "halved", "halved", If(VLOOKUP(INDEX(MatchPlay3, Match(CONCATENATE("*", BlueP5, "*"), MatchPlay3, false), 0),MatchPlay3_VL, 3, false) <> "AS", if(left(VLOOKUP(INDEX(MatchPlay3, Match(CONCATENATE("*", BlueP5, "*"), MatchPlay3, false), 0),MatchPlay3_VL, 3, false), 1) = "a", "W", "L"), "TBD")))} -> L | E33: =SUM(IFS(B33="W", MPPointsW, B33="L", MPPointsL, B33="halved", MPPointsH, B33="TBD", "0"), IFS(C33="W", MPPointsW, C33="L", MPPointsL, C33="halved", MPPointsH, C33="TBD", "0"), IFS(D33="W", MPPointsW, D33="L", MPPointsL, D33="halved", MPPointsH, D33="TBD", "0")) -> #N/A | F33: =IFS(LARGE(MPFlight5Total, 1)=E33, 1, LARGE(MPFlight5Total, 2)=E33, 2, LARGE(MPFlight5Total, 3)=E33, 3, LARGE(MPFlight5Total, 4)=E33, 4) -> #N/A | G33: =If(C33="TBD", 0, F33) -> #N/A | H33: =If(C33="TBD", 0, VLOOKUP(G33,MatchPlayPoints_VL, 2, false)) -> #N/A
A34: =RedP5 -> Powell (R) | B34: {=If(VLOOKUP(INDEX(MatchPlay1, Match(CONCATENATE("*", RedP5, "*"), MatchPlay1, false), 0),MatchPlay1_VL, 2, false) = 0, "TBD", if(VLOOKUP(INDEX(MatchPlay1, Match(CONCATENATE("*", RedP5, "*"), MatchPlay1, false), 0),MatchPlay1_VL, 3, false) = "halved", "halved", If(VLOOKUP(INDEX(MatchPlay1, Match(CONCATENATE("*", RedP5, "*"), MatchPlay1, false), 0),MatchPlay1_VL, 3, false) <> "AS", if(left(VLOOKUP(INDEX(MatchPlay1, Match(CONCATENATE("*", RedP5, "*"), MatchPlay1, false), 0),MatchPlay1_VL, 3, false), 1) = "b", "W", "L"), "TBD")))} -> #N/A | C34: {=If(VLOOKUP(INDEX(MatchPlay2, Match(CONCATENATE("*", RedP5, "*"), MatchPlay2, false), 0),MatchPlay2_VL, 2, false) = 0, "TBD", if(VLOOKUP(INDEX(MatchPlay2, Match(CONCATENATE("*", RedP5, "*"), MatchPlay2, false), 0),MatchPlay2_VL, 3, false) = "halved", "halved", If(VLOOKUP(INDEX(MatchPlay2, Match(CONCATENATE("*", RedP5, "*"), MatchPlay2, false), 0),MatchPlay2_VL, 3, false) <> "AS", if(left(VLOOKUP(INDEX(MatchPlay2, Match(CONCATENATE("*", RedP5, "*"), MatchPlay2, false), 0),MatchPlay2_VL, 3, false), 1) = "a", "W", "L"), "TBD")))} -> L | D34: {=If(VLOOKUP(INDEX(MatchPlay3, Match(CONCATENATE("*", RedP5, "*"), MatchPlay3, false), 0),MatchPlay3_VL, 2, false) = 0, "TBD", if(VLOOKUP(INDEX(MatchPlay3, Match(CONCATENATE("*", RedP5, "*"), MatchPlay3, false), 0),MatchPlay3_VL, 3, false) = "halved", "halved", If(VLOOKUP(INDEX(MatchPlay3, Match(CONCATENATE("*", RedP5, "*"), MatchPlay3, false), 0),MatchPlay3_VL, 3, false) <> "AS", if(left(VLOOKUP(INDEX(MatchPlay3, Match(CONCATENATE("*", RedP5, "*"), MatchPlay3, false), 0),MatchPlay3_VL, 3, false), 1) = "b", "W", "L"), "TBD")))} -> #N/A | E34: =SUM(IFS(B34="W", MPPointsW, B34="L", MPPointsL, B34="halved", MPPointsH, B34="TBD", "0"), IFS(C34="W", MPPointsW, C34="L", MPPointsL, C34="halved", MPPointsH, C34="TBD", "0"), IFS(D34="W", MPPointsW, D34="L", MPPointsL, D34="halved", MPPointsH, D34="TBD", "0")) -> #N/A | F34: =IFS(LARGE(MPFlight5Total, 1)=E34, 1, LARGE(MPFlight5Total, 2)=E34, 2, LARGE(MPFlight5Total, 3)=E34, 3, LARGE(MPFlight5Total, 4)=E34, 4) -> #N/A | G34: =If(C34="TBD", 0, F34) -> #N/A | H34: =If(C34="TBD", 0, VLOOKUP(G34,MatchPlayPoints_VL, 2, false)) -> #N/A
A36: FLIGHT 6
A37: Player | B37: M1 | C37: M2 | D37: M3 | E37: Total Points | F37: Flight Finish | G37: Flight Finish | H37: Ryder Cup Points
A38: =WhiteP6 -> Dave (W) | B38: {=If(VLOOKUP(INDEX(MatchPlay1, Match(CONCATENATE("*", WhiteP6, "*"), MatchPlay1, false), 0),MatchPlay1_VL, 2, false) = 0, "TBD", if(VLOOKUP(INDEX(MatchPlay1, Match(CONCATENATE("*", WhiteP6, "*"), MatchPlay1, false), 0),MatchPlay1_VL, 3, false) = "halved", "halved", If(VLOOKUP(INDEX(MatchPlay1, Match(CONCATENATE("*", WhiteP6, "*"), MatchPlay1, false), 0),MatchPlay1_VL, 3, false) <> "AS", if(left(VLOOKUP(INDEX(MatchPlay1, Match(CONCATENATE("*", WhiteP6, "*"), MatchPlay1, false), 0),MatchPlay1_VL, 3, false), 1) = "a", "W", "L"), "TBD")))} -> L | C38: {=If(VLOOKUP(INDEX(MatchPlay2, Match(CONCATENATE("*", WhiteP6, "*"), MatchPlay2, false), 0),MatchPlay2_VL, 2, false) = 0, "TBD", if(VLOOKUP(INDEX(MatchPlay2, Match(CONCATENATE("*", WhiteP6, "*"), MatchPlay2, false), 0),MatchPlay2_VL, 3, false) = "halved", "halved", If(VLOOKUP(INDEX(MatchPlay2, Match(CONCATENATE("*", WhiteP6, "*"), MatchPlay2, false), 0),MatchPlay2_VL, 3, false) <> "AS", if(left(VLOOKUP(INDEX(MatchPlay2, Match(CONCATENATE("*", WhiteP6, "*"), MatchPlay2, false), 0),MatchPlay2_VL, 3, false), 1) = "a", "W", "L"), "TBD")))} -> L | D38: {=If(VLOOKUP(INDEX(MatchPlay3, Match(CONCATENATE("*", WhiteP6, "*"), MatchPlay3, false), 0),MatchPlay3_VL, 2, false) = 0, "TBD", if(VLOOKUP(INDEX(MatchPlay3, Match(CONCATENATE("*", WhiteP6, "*"), MatchPlay3, false), 0),MatchPlay3_VL, 3, false) = "halved", "halved", If(VLOOKUP(INDEX(MatchPlay3, Match(CONCATENATE("*", WhiteP6, "*"), MatchPlay3, false), 0),MatchPlay3_VL, 3, false) <> "AS", if(left(VLOOKUP(INDEX(MatchPlay3, Match(CONCATENATE("*", WhiteP6, "*"), MatchPlay3, false), 0),MatchPlay3_VL, 3, false), 1) = "a", "W", "L"), "TBD")))} -> L | E38: =SUM(IFS(B38="W", MPPointsW, B38="L", MPPointsL, B38="halved", MPPointsH, B38="TBD", "0"), IFS(C38="W", MPPointsW, C38="L", MPPointsL, C38="halved", MPPointsH, C38="TBD", "0"), IFS(D38="W", MPPointsW, D38="L", MPPointsL, D38="halved", MPPointsH, D38="TBD", "0")) -> 0 | F38: =IFS(LARGE(MPFlight6Total, 1)=E38, 1, LARGE(MPFlight6Total, 2)=E38, 2, LARGE(MPFlight6Total, 3)=E38, 3, LARGE(MPFlight6Total, 4)=E38, 4) -> #N/A | G38: =If(C38="TBD", 0, F38) -> #N/A | H38: =If(C38="TBD", 0, VLOOKUP(G38,MatchPlayPoints_VL, 2, false)) -> #N/A
A39: =BlackP6 -> Neil (A) | B39: {=If(VLOOKUP(INDEX(MatchPlay1, Match(CONCATENATE("*", BlackP6, "*"), MatchPlay1, false), 0),MatchPlay1_VL, 2, false) = 0, "TBD", if(VLOOKUP(INDEX(MatchPlay1, Match(CONCATENATE("*", BlackP6, "*"), MatchPlay1, false), 0),MatchPlay1_VL, 3, false) = "halved", "halved", If(VLOOKUP(INDEX(MatchPlay1, Match(CONCATENATE("*", BlackP6, "*"), MatchPlay1, false), 0),MatchPlay1_VL, 3, false) <> "AS", if(left(VLOOKUP(INDEX(MatchPlay1, Match(CONCATENATE("*", BlackP6, "*"), MatchPlay1, false), 0),MatchPlay1_VL, 3, false), 1) = "b", "W", "L"), "TBD")))} -> #N/A | C39: {=If(VLOOKUP(INDEX(MatchPlay2, Match(CONCATENATE("*", BlackP6, "*"), MatchPlay2, false), 0),MatchPlay2_VL, 2, false) = 0, "TBD", if(VLOOKUP(INDEX(MatchPlay2, Match(CONCATENATE("*", BlackP6, "*"), MatchPlay2, false), 0),MatchPlay2_VL, 3, false) = "halved", "halved", If(VLOOKUP(INDEX(MatchPlay2, Match(CONCATENATE("*", BlackP6, "*"), MatchPlay2, false), 0),MatchPlay2_VL, 3, false) <> "AS", if(left(VLOOKUP(INDEX(MatchPlay2, Match(CONCATENATE("*", BlackP6, "*"), MatchPlay2, false), 0),MatchPlay2_VL, 3, false), 1) = "b", "W", "L"), "TBD")))} -> #N/A | D39: {=If(VLOOKUP(INDEX(MatchPlay3, Match(CONCATENATE("*", BlackP6, "*"), MatchPlay3, false), 0),MatchPlay3_VL, 2, false) = 0, "TBD", if(VLOOKUP(INDEX(MatchPlay3, Match(CONCATENATE("*", BlackP6, "*"), MatchPlay3, false), 0),MatchPlay3_VL, 3, false) = "halved", "halved", If(VLOOKUP(INDEX(MatchPlay3, Match(CONCATENATE("*", BlackP6, "*"), MatchPlay3, false), 0),MatchPlay3_VL, 3, false) <> "AS", if(left(VLOOKUP(INDEX(MatchPlay3, Match(CONCATENATE("*", BlackP6, "*"), MatchPlay3, false), 0),MatchPlay3_VL, 3, false), 1) = "a", "W", "L"), "TBD")))} -> L | E39: =SUM(IFS(B39="W", MPPointsW, B39="L", MPPointsL, B39="halved", MPPointsH, B39="TBD", "0"), IFS(C39="W", MPPointsW, C39="L", MPPointsL, C39="halved", MPPointsH, C39="TBD", "0"), IFS(D39="W", MPPointsW, D39="L", MPPointsL, D39="halved", MPPointsH, D39="TBD", "0")) -> #N/A | F39: =IFS(LARGE(MPFlight6Total, 1)=E39, 1, LARGE(MPFlight6Total, 2)=E39, 2, LARGE(MPFlight6Total, 3)=E39, 3, LARGE(MPFlight6Total, 4)=E39, 4) -> #N/A | G39: =If(C39="TBD", 0, F39) -> #N/A | H39: =If(C39="TBD", 0, VLOOKUP(G39,MatchPlayPoints_VL, 2, false)) -> #N/A
A40: =BlueP6 -> Matt (B) | B40: {=If(VLOOKUP(INDEX(MatchPlay1, Match(CONCATENATE("*", BlueP6, "*"), MatchPlay1, false), 0),MatchPlay1_VL, 2, false) = 0, "TBD", if(VLOOKUP(INDEX(MatchPlay1, Match(CONCATENATE("*", BlueP6, "*"), MatchPlay1, false), 0),MatchPlay1_VL, 3, false) = "halved", "halved", If(VLOOKUP(INDEX(MatchPlay1, Match(CONCATENATE("*", BlueP6, "*"), MatchPlay1, false), 0),MatchPlay1_VL, 3, false) <> "AS", if(left(VLOOKUP(INDEX(MatchPlay1, Match(CONCATENATE("*", BlueP6, "*"), MatchPlay1, false), 0),MatchPlay1_VL, 3, false), 1) = "b", "W", "L"), "TBD")))} -> #N/A | C40: {=If(VLOOKUP(INDEX(MatchPlay2, Match(CONCATENATE("*", BlueP6, "*"), MatchPlay2, false), 0),MatchPlay2_VL, 2, false) = 0, "TBD", if(VLOOKUP(INDEX(MatchPlay2, Match(CONCATENATE("*", BlueP6, "*"), MatchPlay2, false), 0),MatchPlay2_VL, 3, false) = "halved", "halved", If(VLOOKUP(INDEX(MatchPlay2, Match(CONCATENATE("*", BlueP6, "*"), MatchPlay2, false), 0),MatchPlay2_VL, 3, false) <> "AS", if(left(VLOOKUP(INDEX(MatchPlay2, Match(CONCATENATE("*", BlueP6, "*"), MatchPlay2, false), 0),MatchPlay2_VL, 3, false), 1) = "a", "W", "L"), "TBD")))} -> L | D40: {=If(VLOOKUP(INDEX(MatchPlay3, Match(CONCATENATE("*", BlueP6, "*"), MatchPlay3, false), 0),MatchPlay3_VL, 2, false) = 0, "TBD", if(VLOOKUP(INDEX(MatchPlay3, Match(CONCATENATE("*", BlueP6, "*"), MatchPlay3, false), 0),MatchPlay3_VL, 3, false) = "halved", "halved", If(VLOOKUP(INDEX(MatchPlay3, Match(CONCATENATE("*", BlueP6, "*"), MatchPlay3, false), 0),MatchPlay3_VL, 3, false) <> "AS", if(left(VLOOKUP(INDEX(MatchPlay3, Match(CONCATENATE("*", BlueP6, "*"), MatchPlay3, false), 0),MatchPlay3_VL, 3, false), 1) = "b", "W", "L"), "TBD")))} -> #N/A | E40: =SUM(IFS(B40="W", MPPointsW, B40="L", MPPointsL, B40="halved", MPPointsH, B40="TBD", "0"), IFS(C40="W", MPPointsW, C40="L", MPPointsL, C40="halved", MPPointsH, C40="TBD", "0"), IFS(D40="W", MPPointsW, D40="L", MPPointsL, D40="halved", MPPointsH, D40="TBD", "0")) -> #N/A | F40: =IFS(LARGE(MPFlight6Total, 1)=E40, 1, LARGE(MPFlight6Total, 2)=E40, 2, LARGE(MPFlight6Total, 3)=E40, 3, LARGE(MPFlight6Total, 4)=E40, 4) -> #N/A | G40: 2 | H40: =If(C40="TBD", 0, VLOOKUP(G40,MatchPlayPoints_VL, 2, false)) -> 1
