Workbook
Name Round1: Leaderboard!$E:$E
Name Round2: Leaderboard!$F:$F
Name Tier2: 'Player Tiers'!$B$2:$B$34
Name Round4: Leaderboard!$H:$H
Name PositionLeaderboard: Leaderboard!$B:$B
Name Tier3: 'Player Tiers'!$C$2:$C$56
Name Round3: Leaderboard!$G:$G
Name LowRound2: Leaderboard!$N$2
Name Tier1: 'Player Tiers'!$A$2:$A$31
Name Points: Scoring!$B$1:$B$7
Name LowRound1: Leaderboard!$M$2
Name LowRound3: Leaderboard!$O$2
Name Tier4: 'Player Tiers'!$D$2:$D$67
Name LowRound4: Leaderboard!$P$2
Name PlayerLeaderboard: Leaderboard!$C:$C
Name PointNames: Scoring!$A$1:$A$7

Sheet Testing
A1: =year(today()) & month(today()) & day(today()) & hour(today()) & minute(today()) -> 20264400
A2: http://www.espn.com/golf/leaderboard?
A3: =IFERROR(__xludf.DUMMYFUNCTION("ImportHtml(A2,""table"",3)"),"#N/A") -> #N/A

Sheet Live Leaderboard
A1: Live Scoreboard
A2: {=Sort('Team Scoreboard'!E2:F36,2,false)} -> Rocky | B2: 58 | C2: 1st
A3: Member's Bounce | B3: 45 | C3: 2nd
A4: Johnson Wagner | B4: 44 | C4: 3rd
A5: Putt Blugs | B5: 38
A6: Shankapotamus ⛳️ | B6: 35
A7: Bizzle Bone 🦴 | B7: 34
A8: Shooter's Turn | B8: 33
A9: Wish Louis was Playing | B9: 30
A10: Hosel Rocket | B10: 30
A11: And33znutz | B11: 28
A12: ParTee Animals | B12: 28
A13: Baseball Hacks Only | B13: 28
A14: Rob Won | B14: 26
A15: The Putt Pirates | B15: 22 | C15: `
A16: It's all in the hips | B16: 21
A17: Magnolia Lane | B17: 17
A18: Better Than Most | B18: 14
A19: Back to back to back | B19: 14
A20: Nova | B20: 14
A21: Scottie Style | B21: 12
A22: 9 O'clock on the 9th Green | B22: 9
A23: Good Good Good | B23: 9
A24: Kyle Beeler | B24: 9
A25: Maher | B25: 7
A26: Vandegriff | B26: 7
A27: Kroll's Holes | B27: 7
... A31: Only Boss That Has Won this Before | B31: -3

Sheet Team Scoreboard
A1: ='Pickem Board'!B3 -> Shankapotamus ⛳️ | B1: Position | C1: Points | D1: Low Round Points | E1: SCOREBOARD
A2: ='Pickem Board'!B4 -> Rory McIlroy | B2: {=If(Substitute(Index(PositionLeaderboard, Match(A2,PlayerLeaderboard, 0)), "T", "") = "-", "-", Value(Substitute(Index(PositionLeaderboard, Match(A2,PlayerLeaderboard, 0)), "T", "")))} -> 1 | C2: {=INDEX(Points, Match(If(AND(B2>3,B2<11),"Top 10", If(AND(B2>10,NOT(B2=""), B2<26),"Top 25", If(B2="-","Missed Cut", If(B2>25,"Made Cut",B2)))),PointNames, 0))} -> 25 | D2: {=2*(SUM(If(Index(Round1, Match(A2,PlayerLeaderboard, 0))=LowRound1, 1, 0), If(Index(Round2, Match(A2,PlayerLeaderboard, 0))=LowRound2, 1, 0), If(Index(Round3, Match(A2,PlayerLeaderboard, 0))=LowRound3, 1, 0), If(Index(Round4, Match(A2,PlayerLeaderboard, 0))=LowRound4, 1, 0)))} -> 4 | E2: =A1 -> Shankapotamus ⛳️ | F2: =C6 -> 35
A3: ='Pickem Board'!B5 -> Jordan Spieth | B3: {=If(Substitute(Index(PositionLeaderboard, Match(A3,PlayerLeaderboard, 0)), "T", "") = "-", "-", Value(Substitute(Index(PositionLeaderboard, Match(A3,PlayerLeaderboard, 0)), "T", "")))} -> 14 | C3: {=INDEX(Points, Match(If(AND(B3>3,B3<11),"Top 10", If(AND(B3>10,NOT(B3=""), B3<26),"Top 25", If(B3="-","Missed Cut", If(B3>25,"Made Cut",B3)))),PointNames, 0))} -> 5 | D3: {=2*(SUM(If(Index(Round1, Match(A3,PlayerLeaderboard, 0))=LowRound1, 1, 0), If(Index(Round2, Match(A3,PlayerLeaderboard, 0))=LowRound2, 1, 0), If(Index(Round3, Match(A3,PlayerLeaderboard, 0))=LowRound3, 1, 0), If(Index(Round4, Match(A3,PlayerLeaderboard, 0))=LowRound4, 1, 0)))} -> 0 | E3: =A8 -> 9 O'clock on the 9th Green | F3: =C13 -> 9
A4: ='Pickem Board'!B6 -> Sahith Theegala | B4: {=If(Substitute(Index(PositionLeaderboard, Match(A4,PlayerLeaderboard, 0)), "T", "") = "-", "-", Value(Substitute(Index(PositionLeaderboard, Match(A4,PlayerLeaderboard, 0)), "T", "")))} -> 29 | C4: {=INDEX(Points, Match(If(AND(B4>3,B4<11),"Top 10", If(AND(B4>10,NOT(B4=""), B4<26),"Top 25", If(B4="-","Missed Cut", If(B4>25,"Made Cut",B4)))),PointNames, 0))} -> 3 | D4: {=2*(SUM(If(Index(Round1, Match(A4,PlayerLeaderboard, 0))=LowRound1, 1, 0), If(Index(Round2, Match(A4,PlayerLeaderboard, 0))=LowRound2, 1, 0), If(Index(Round3, Match(A4,PlayerLeaderboard, 0))=LowRound3, 1, 0), If(Index(Round4, Match(A4,PlayerLeaderboard, 0))=LowRound4, 1, 0)))} -> 0 | E4: =A15 -> Better Than Most | F4: =C20 -> 14
A5: ='Pickem Board'!B7 -> Cam Davis | B5: {=If(Substitute(Index(PositionLeaderboard, Match(A5,PlayerLeaderboard, 0)), "T", "") = "-", "-", Value(Substitute(Index(PositionLeaderboard, Match(A5,PlayerLeaderboard, 0)), "T", "")))} -> - | C5: {=INDEX(Points, Match(If(AND(B5>3,B5<11),"Top 10", If(AND(B5>10,NOT(B5=""), B5<26),"Top 25", If(B5="-","Missed Cut", If(B5>25,"Made Cut",B5)))),PointNames, 0))} -> -2 | D5: {=2*(SUM(If(Index(Round1, Match(A5,PlayerLeaderboard, 0))=LowRound1, 1, 0), If(Index(Round2, Match(A5,PlayerLeaderboard, 0))=LowRound2, 1, 0), If(Index(Round3, Match(A5,PlayerLeaderboard, 0))=LowRound3, 1, 0), If(Index(Round4, Match(A5,PlayerLeaderboard, 0))=LowRound4, 1, 0)))} -> 0 | E5: =A22 -> Maher | F5: =C27 -> 7
A6: Total Points | C6: =SUM(C2:C5)+SUM(D2:D5) -> 35 | E6: =A29 -> Wish Louis was Playing | F6: =C34 -> 30
E7: =A36 -> Putts n' Stuff | F7: =C41 -> 4
A8: ='Pickem Board'!C3 -> 9 O'clock on the 9th Green | B8: Position | C8: Points | D8: Low Round Points | E8: =A43 -> Scottie Style | F8: =C48 -> 12
A9: ='Pickem Board'!C4 -> Scottie Scheffler | B9: {=If(Substitute(Index(PositionLeaderboard, Match(A9,PlayerLeaderboard, 0)), "T", "") = "-", "-", Value(Substitute(Index(PositionLeaderboard, Match(A9,PlayerLeaderboard, 0)), "T", "")))} -> 4 | C9: {=INDEX(Points, Match(If(AND(B9>3,B9<11),"Top 10", If(AND(B9>10,NOT(B9=""), B9<26),"Top 25", If(B9="-","Missed Cut", If(B9>25,"Made Cut",B9)))),PointNames, 0))} -> 8 | D9: {=2*(SUM(If(Index(Round1, Match(A9,PlayerLeaderboard, 0))=LowRound1, 1, 0), If(Index(Round2, Match(A9,PlayerLeaderboard, 0))=LowRound2, 1, 0), If(Index(Round3, Match(A9,PlayerLeaderboard, 0))=LowRound3, 1, 0), If(Index(Round4, Match(A9,PlayerLeaderboard, 0))=LowRound4, 1, 0)))} -> 0 | E9: =A50 -> Back to back to back | F9: =C55 -> 14
A10: ='Pickem Board'!C5 -> Tommy Fleetwood | B10: {=If(Substitute(Index(PositionLeaderboard, Match(A10,PlayerLeaderboard, 0)), "T", "") = "-", "-", Value(Substitute(Index(PositionLeaderboard, Match(A10,PlayerLeaderboard, 0)), "T", "")))} -> 21 | C10: {=INDEX(Points, Match(If(AND(B10>3,B10<11),"Top 10", If(AND(B10>10,NOT(B10=""), B10<26),"Top 25", If(B10="-","Missed Cut", If(B10>25,"Made Cut",B10)))),PointNames, 0))} -> 5 | D10: {=2*(SUM(If(Index(Round1, Match(A10,PlayerLeaderboard, 0))=LowRound1, 1, 0), If(Index(Round2, Match(A10,PlayerLeaderboard, 0))=LowRound2, 1, 0), If(Index(Round3, Match(A10,PlayerLeaderboard, 0))=LowRound3, 1, 0), If(Index(Round4, Match(A10,PlayerLeaderboard, 0))=LowRound4, 1, 0)))} -> 0 | E10: =A57 -> And33znutz | F10: =C62 -> 28
A11: ='Pickem Board'!C6 -> Sepp Straka | B11: {=If(Substitute(Index(PositionLeaderboard, Match(A11,PlayerLeaderboard, 0)), "T", "") = "-", "-", Value(Substitute(Index(PositionLeaderboard, Match(A11,PlayerLeaderboard, 0)), "T", "")))} -> - | C11: {=INDEX(Points, Match(If(AND(B11>3,B11<11),"Top 10", If(AND(B11>10,NOT(B11=""), B11<26),"Top 25", If(B11="-","Missed Cut", If(B11>25,"Made Cut",B11)))),PointNames, 0))} -> -2 | D11: {=2*(SUM(If(Index(Round1, Match(A11,PlayerLeaderboard, 0))=LowRound1, 1, 0), If(Index(Round2, Match(A11,PlayerLeaderboard, 0))=LowRound2, 1, 0), If(Index(Round3, Match(A11,PlayerLeaderboard, 0))=LowRound3, 1, 0), If(Index(Round4, Match(A11,PlayerLeaderboard, 0))=LowRound4, 1, 0)))} -> 0 | E11: =A64 -> Magnolia Lane | F11: =C69 -> 17
A12: ='Pickem Board'!C7 -> Thomas Detry | B12: {=If(Substitute(Index(PositionLeaderboard, Match(A12,PlayerLeaderboard, 0)), "T", "") = "-", "-", Value(Substitute(Index(PositionLeaderboard, Match(A12,PlayerLeaderboard, 0)), "T", "")))} -> - | C12: {=INDEX(Points, Match(If(AND(B12>3,B12<11),"Top 10", If(AND(B12>10,NOT(B12=""), B12<26),"Top 25", If(B12="-","Missed Cut", If(B12>25,"Made Cut",B12)))),PointNames, 0))} -> -2 | D12: {=2*(SUM(If(Index(Round1, Match(A12,PlayerLeaderboard, 0))=LowRound1, 1, 0), If(Index(Round2, Match(A12,PlayerLeaderboard, 0))=LowRound2, 1, 0), If(Index(Round3, Match(A12,PlayerLeaderboard, 0))=LowRound3, 1, 0), If(Index(Round4, Match(A12,PlayerLeaderboard, 0))=LowRound4, 1, 0)))} -> 0 | E12: =A71 -> Shooter's Turn | F12: =C76 -> 33
A13: Total Points | C13: =SUM(C9:C12)+SUM(D9:D12) -> 9 | E13: =A78 -> It's all in the hips | F13: =C83 -> 21
E14: =A85 -> Member's Bounce | F14: =C90 -> 45
A15: ='Pickem Board'!D3 -> Better Than Most | B15: Position | C15: Points | D15: Low Round Points | E15: =A92 -> Nova | F15: =C97 -> 14
A16: ='Pickem Board'!D4 -> Scottie Scheffler | B16: {=If(Substitute(Index(PositionLeaderboard, Match(A16,PlayerLeaderboard, 0)), "T", "") = "-", "-", Value(Substitute(Index(PositionLeaderboard, Match(A16,PlayerLeaderboard, 0)), "T", "")))} -> 4 | C16: {=INDEX(Points, Match(If(AND(B16>3,B16<11),"Top 10", If(AND(B16>10,NOT(B16=""), B16<26),"Top 25", If(B16="-","Missed Cut", If(B16>25,"Made Cut",B16)))),PointNames, 0))} -> 8 | D16: {=2*(SUM(If(Index(Round1, Match(A16,PlayerLeaderboard, 0))=LowRound1, 1, 0), If(Index(Round2, Match(A16,PlayerLeaderboard, 0))=LowRound2, 1, 0), If(Index(Round3, Match(A16,PlayerLeaderboard, 0))=LowRound3, 1, 0), If(Index(Round4, Match(A16,PlayerLeaderboard, 0))=LowRound4, 1, 0)))} -> 0 | E16: =A99 -> Vandegriff | F16: =C104 -> 7
A17: ='Pickem Board'!D5 -> Viktor Hovland | B17: {=If(Substitute(Index(PositionLeaderboard, Match(A17,PlayerLeaderboard, 0)), "T", "") = "-", "-", Value(Substitute(Index(PositionLeaderboard, Match(A17,PlayerLeaderboard, 0)), "T", "")))} -> 21 | C17: {=INDEX(Points, Match(If(AND(B17>3,B17<11),"Top 10", If(AND(B17>10,NOT(B17=""), B17<26),"Top 25", If(B17="-","Missed Cut", If(B17>25,"Made Cut",B17)))),PointNames, 0))} -> 5 | D17: {=2*(SUM(If(Index(Round1, Match(A17,PlayerLeaderboard, 0))=LowRound1, 1, 0), If(Index(Round2, Match(A17,PlayerLeaderboard, 0))=LowRound2, 1, 0), If(Index(Round3, Match(A17,PlayerLeaderboard, 0))=LowRound3, 1, 0), If(Index(Round4, Match(A17,PlayerLeaderboard, 0))=LowRound4, 1, 0)))} -> 0 | E17: =A106 -> Good Good Good | F17: =C111 -> 9
A18: ='Pickem Board'!D6 -> Sam Burns | B18: {=If(Substitute(Index(PositionLeaderboard, Match(A18,PlayerLeaderboard, 0)), "T", "") = "-", "-", Value(Substitute(Index(PositionLeaderboard, Match(A18,PlayerLeaderboard, 0)), "T", "")))} -> 46 | C18: {=INDEX(Points, Match(If(AND(B18>3,B18<11),"Top 10", If(AND(B18>10,NOT(B18=""), B18<26),"Top 25", If(B18="-","Missed Cut", If(B18>25,"Made Cut",B18)))),PointNames, 0))} -> 3 | D18: {=2*(SUM(If(Index(Round1, Match(A18,PlayerLeaderboard, 0))=LowRound1, 1, 0), If(Index(Round2, Match(A18,PlayerLeaderboard, 0))=LowRound2, 1, 0), If(Index(Round3, Match(A18,PlayerLeaderboard, 0))=LowRound3, 1, 0), If(Index(Round4, Match(A18,PlayerLeaderboard, 0))=LowRound4, 1, 0)))} -> 0 | E18: =A113 -> Kyle Beeler | F18: =C118 -> 9
A19: ='Pickem Board'!D7 -> Cameron Young | B19: {=If(Substitute(Index(PositionLeaderboard, Match(A19,PlayerLeaderboard, 0)), "T", "") = "-", "-", Value(Substitute(Index(PositionLeaderboard, Match(A19,PlayerLeaderboard, 0)), "T", "")))} -> - | C19: {=INDEX(Points, Match(If(AND(B19>3,B19<11),"Top 10", If(AND(B19>10,NOT(B19=""), B19<26),"Top 25", If(B19="-","Missed Cut", If(B19>25,"Made Cut",B19)))),PointNames, 0))} -> -2 | D19: {=2*(SUM(If(Index(Round1, Match(A19,PlayerLeaderboard, 0))=LowRound1, 1, 0), If(Index(Round2, Match(A19,PlayerLeaderboard, 0))=LowRound2, 1, 0), If(Index(Round3, Match(A19,PlayerLeaderboard, 0))=LowRound3, 1, 0), If(Index(Round4, Match(A19,PlayerLeaderboard, 0))=LowRound4, 1, 0)))} -> 0 | E19: =A120 -> Faldo & Barker | F19: =C125 -> 4
A20: Total Points | C20: =SUM(C16:C19)+SUM(D16:D19) -> 14 | E20: =A127 -> Kroll's Holes | F20: =C132 -> 7
E21: =A134 -> The Putt Pirates | F21: =C139 -> 22
A22: ='Pickem Board'!E3 -> Maher | B22: Position | C22: Points | D22: Low Round Points | E22: =A141 -> Bizzle Bone 🦴 | F22: =C146 -> 34
A23: ='Pickem Board'!E4 -> Scottie Scheffler | B23: {=If(Substitute(Index(PositionLeaderboard, Match(A23,PlayerLeaderboard, 0)), "T", "") = "-", "-", Value(Substitute(Index(PositionLeaderboard, Match(A23,PlayerLeaderboard, 0)), "T", "")))} -> 4 | C23: {=INDEX(Points, Match(If(AND(B23>3,B23<11),"Top 10", If(AND(B23>10,NOT(B23=""), B23<26),"Top 25", If(B23="-","Missed Cut", If(B23>25,"Made Cut",B23)))),PointNames, 0))} -> 8 | D23: {=2*(SUM(If(Index(Round1, Match(A23,PlayerLeaderboard, 0))=LowRound1, 1, 0), If(Index(Round2, Match(A23,PlayerLeaderboard, 0))=LowRound2, 1, 0), If(Index(Round3, Match(A23,PlayerLeaderboard, 0))=LowRound3, 1, 0), If(Index(Round4, Match(A23,PlayerLeaderboard, 0))=LowRound4, 1, 0)))} -> 0 | E23: =A148 -> Rob Won | F23: =C153 -> 26
A24: ='Pickem Board'!E5 -> Brooks Koepka | B24: {=If(Substitute(Index(PositionLeaderboard, Match(A24,PlayerLeaderboard, 0)), "T", "") = "-", "-", Value(Substitute(Index(PositionLeaderboard, Match(A24,PlayerLeaderboard, 0)), "T", "")))} -> - | C24: {=INDEX(Points, Match(If(AND(B24>3,B24<11),"Top 10", If(AND(B24>10,NOT(B24=""), B24<26),"Top 25", If(B24="-","Missed Cut", If(B24>25,"Made Cut",B24)))),PointNames, 0))} -> -2 | D24: {=2*(SUM(If(Index(Round1, Match(A24,PlayerLeaderboard, 0))=LowRound1, 1, 0), If(Index(Round2, Match(A24,PlayerLeaderboard, 0))=LowRound2, 1, 0), If(Index(Round3, Match(A24,PlayerLeaderboard, 0))=LowRound3, 1, 0), If(Index(Round4, Match(A24,PlayerLeaderboard, 0))=LowRound4, 1, 0)))} -> 0 | E24: =A155 -> Rob Won Two | F24: =C160 -> 7
A25: ='Pickem Board'!E6 -> Sergio Garcia | B25: {=If(Substitute(Index(PositionLeaderboard, Match(A25,PlayerLeaderboard, 0)), "T", "") = "-", "-", Value(Substitute(Index(PositionLeaderboard, Match(A25,PlayerLeaderboard, 0)), "T", "")))} -> - | C25: {=INDEX(Points, Match(If(AND(B25>3,B25<11),"Top 10", If(AND(B25>10,NOT(B25=""), B25<26),"Top 25", If(B25="-","Missed Cut", If(B25>25,"Made Cut",B25)))),PointNames, 0))} -> -2 | D25: {=2*(SUM(If(Index(Round1, Match(A25,PlayerLeaderboard, 0))=LowRound1, 1, 0), If(Index(Round2, Match(A25,PlayerLeaderboard, 0))=LowRound2, 1, 0), If(Index(Round3, Match(A25,PlayerLeaderboard, 0))=LowRound3, 1, 0), If(Index(Round4, Match(A25,PlayerLeaderboard, 0))=LowRound4, 1, 0)))} -> 0 | E25: =A162 -> Only Boss That Has Won this Before | F25: =C167 -> -3
A26: ='Pickem Board'!E7 -> Danny Willett | B26: {=If(Substitute(Index(PositionLeaderboard, Match(A26,PlayerLeaderboard, 0)), "T", "") = "-", "-", Value(Substitute(Index(PositionLeaderboard, Match(A26,PlayerLeaderboard, 0)), "T", "")))} -> 42 | C26: {=INDEX(Points, Match(If(AND(B26>3,B26<11),"Top 10", If(AND(B26>10,NOT(B26=""), B26<26),"Top 25", If(B26="-","Missed Cut", If(B26>25,"Made Cut",B26)))),PointNames, 0))} -> 3 | D26: {=2*(SUM(If(Index(Round1, Match(A26,PlayerLeaderboard, 0))=LowRound1, 1, 0), If(Index(Round2, Match(A26,PlayerLeaderboard, 0))=LowRound2, 1, 0), If(Index(Round3, Match(A26,PlayerLeaderboard, 0))=LowRound3, 1, 0), If(Index(Round4, Match(A26,PlayerLeaderboard, 0))=LowRound4, 1, 0)))} -> 0 | E26: =A169 -> Johnson Wagner | F26: =C174 -> 44
A27: Total Points | C27: =SUM(C23:C26)+SUM(D23:D26) -> 7 | E27: =A176 -> ParTee Animals | F27: =C181 -> 28
E28: =A183 -> Hosel Rocket | F28: =C188 -> 30
A29: ='Pickem Board'!F3 -> Wish Louis was Playing | B29: Position | C29: Points | D29: Low Round Points | E29: =A190 -> Putt Blugs | F29: =C195 -> 38
A30: ='Pickem Board'!F4 -> Collin Morikawa | B30: {=If(Substitute(Index(PositionLeaderboard, Match(A30,PlayerLeaderboard, 0)), "T", "") = "-", "-", Value(Substitute(Index(PositionLeaderboard, Match(A30,PlayerLeaderboard, 0)), "T", "")))} -> 14 | C30: {=INDEX(Points, Match(If(AND(B30>3,B30<11),"Top 10", If(AND(B30>10,NOT(B30=""), B30<26),"Top 25", If(B30="-","Missed Cut", If(B30>25,"Made Cut",B30)))),PointNames, 0))} -> 5 | D30: {=2*(SUM(If(Index(Round1, Match(A30,PlayerLeaderboard, 0))=LowRound1, 1, 0), If(Index(Round2, Match(A30,PlayerLeaderboard, 0))=LowRound2, 1, 0), If(Index(Round3, Match(A30,PlayerLeaderboard, 0))=LowRound3, 1, 0), If(Index(Round4, Match(A30,PlayerLeaderboard, 0))=LowRound4, 1, 0)))} -> 0 | E30: =A197 -> Baseball Hacks Only | F30: =C202 -> 28
A31: ='Pickem Board'!F5 -> Shane Lowry | B31: {=If(Substitute(Index(PositionLeaderboard, Match(A31,PlayerLeaderboard, 0)), "T", "") = "-", "-", Value(Substitute(Index(PositionLeaderboard, Match(A31,PlayerLeaderboard, 0)), "T", "")))} -> 42 | C31: {=INDEX(Points, Match(If(AND(B31>3,B31<11),"Top 10", If(AND(B31>10,NOT(B31=""), B31<26),"Top 25", If(B31="-","Missed Cut", If(B31>25,"Made Cut",B31)))),PointNames, 0))} -> 3 | D31: {=2*(SUM(If(Index(Round1, Match(A31,PlayerLeaderboard, 0))=LowRound1, 1, 0), If(Index(Round2, Match(A31,PlayerLeaderboard, 0))=LowRound2, 1, 0), If(Index(Round3, Match(A31,PlayerLeaderboard, 0))=LowRound3, 1, 0), If(Index(Round4, Match(A31,PlayerLeaderboard, 0))=LowRound4, 1, 0)))} -> 0 | E31: =A204 -> Rocky | F31: =C209 -> 58
A32: ='Pickem Board'!F6 -> Justin Rose | B32: {=If(Substitute(Index(PositionLeaderboard, Match(A32,PlayerLeaderboard, 0)), "T", "") = "-", "-", Value(Substitute(Index(PositionLeaderboard, Match(A32,PlayerLeaderboard, 0)), "T", "")))} -> 2 | C32: {=INDEX(Points, Match(If(AND(B32>3,B32<11),"Top 10", If(AND(B32>10,NOT(B32=""), B32<26),"Top 25", If(B32="-","Missed Cut", If(B32>25,"Made Cut",B32)))),PointNames, 0))} -> 15 | D32: {=2*(SUM(If(Index(Round1, Match(A32,PlayerLeaderboard, 0))=LowRound1, 1, 0), If(Index(Round2, Match(A32,PlayerLeaderboard, 0))=LowRound2, 1, 0), If(Index(Round3, Match(A32,PlayerLeaderboard, 0))=LowRound3, 1, 0), If(Index(Round4, Match(A32,PlayerLeaderboard, 0))=LowRound4, 1, 0)))} -> 4
A33: ='Pickem Board'!F7 -> Michael Kim | B33: {=If(Substitute(Index(PositionLeaderboard, Match(A33,PlayerLeaderboard, 0)), "T", "") = "-", "-", Value(Substitute(Index(PositionLeaderboard, Match(A33,PlayerLeaderboard, 0)), "T", "")))} -> 27 | C33: {=INDEX(Points, Match(If(AND(B33>3,B33<11),"Top 10", If(AND(B33>10,NOT(B33=""), B33<26),"Top 25", If(B33="-","Missed Cut", If(B33>25,"Made Cut",B33)))),PointNames, 0))} -> 3 | D33: {=2*(SUM(If(Index(Round1, Match(A33,PlayerLeaderboard, 0))=LowRound1, 1, 0), If(Index(Round2, Match(A33,PlayerLeaderboard, 0))=LowRound2, 1, 0), If(Index(Round3, Match(A33,PlayerLeaderboard, 0))=LowRound3, 1, 0), If(Index(Round4, Match(A33,PlayerLeaderboard, 0))=LowRound4, 1, 0)))} -> 0
A34: Total Points | C34: =SUM(C30:C33)+SUM(D30:D33) -> 30
A36: ='Pickem Board'!G3 -> Putts n' Stuff | B36: Position | C36: Points | D36: Low Round Points
A37: ='Pickem Board'!G4 -> Collin Morikawa | B37: {=If(Substitute(Index(PositionLeaderboard, Match(A37,PlayerLeaderboard, 0)), "T", "") = "-", "-", Value(Substitute(Index(PositionLeaderboard, Match(A37,PlayerLeaderboard, 0)), "T", "")))} -> 14 | C37: {=INDEX(Points, Match(If(AND(B37>3,B37<11),"Top 10", If(AND(B37>10,NOT(B37=""), B37<26),"Top 25", If(B37="-","Missed Cut", If(B37>25,"Made Cut",B37)))),PointNames, 0))} -> 5 | D37: {=2*(SUM(If(Index(Round1, Match(A37,PlayerLeaderboard, 0))=LowRound1, 1, 0), If(Index(Round2, Match(A37,PlayerLeaderboard, 0))=LowRound2, 1, 0), If(Index(Round3, Match(A37,PlayerLeaderboard, 0))=LowRound3, 1, 0), If(Index(Round4, Match(A37,PlayerLeaderboard, 0))=LowRound4, 1, 0)))} -> 0
A38: ='Pickem Board'!G5 -> Patrick Cantlay | B38: {=If(Substitute(Index(PositionLeaderboard, Match(A38,PlayerLeaderboard, 0)), "T", "") = "-", "-", Value(Substitute(Index(PositionLeaderboard, Match(A38,PlayerLeaderboard, 0)), "T", "")))} -> 36 | C38: {=INDEX(Points, Match(If(AND(B38>3,B38<11),"Top 10", If(AND(B38>10,NOT(B38=""), B38<26),"Top 25", If(B38="-","Missed Cut", If(B38>25,"Made Cut",B38)))),PointNames, 0))} -> 3 | D38: {=2*(SUM(If(Index(Round1, Match(A38,PlayerLeaderboard, 0))=LowRound1, 1, 0), If(Index(Round2, Match(A38,PlayerLeaderboard, 0))=LowRound2, 1, 0), If(Index(Round3, Match(A38,PlayerLeaderboard, 0))=LowRound3, 1, 0), If(Index(Round4, Match(A38,PlayerLeaderboard, 0))=LowRound4, 1, 0)))} -> 0
A39: ='Pickem Board'!G6 -> Dustin Johnson | B39: {=If(Substitute(Index(PositionLeaderboard, Match(A39,PlayerLeaderboard, 0)), "T", "") = "-", "-", Value(Substitute(Index(PositionLeaderboard, Match(A39,PlayerLeaderboard, 0)), "T", "")))} -> - | C39: {=INDEX(Points, Match(If(AND(B39>3,B39<11),"Top 10", If(AND(B39>10,NOT(B39=""), B39<26),"Top 25", If(B39="-","Missed Cut", If(B39>25,"Made Cut",B39)))),PointNames, 0))} -> -2 | D39: {=2*(SUM(If(Index(Round1, Match(A39,PlayerLeaderboard, 0))=LowRound1, 1, 0), If(Index(Round2, Match(A39,PlayerLeaderboard, 0))=LowRound2, 1, 0), If(Index(Round3, Match(A39,PlayerLeaderboard, 0))=LowRound3, 1, 0), If(Index(Round4, Match(A39,PlayerLeaderboard, 0))=LowRound4, 1, 0)))} -> 0
A40: ='Pickem Board'!G7 -> Cameron Young | B40: {=If(Substitute(Index(PositionLeaderboard, Match(A40,PlayerLeaderboard, 0)), "T", "") = "-", "-", Value(Substitute(Index(PositionLeaderboard, Match(A40,PlayerLeaderboard, 0)), "T", "")))} -> - | C40: {=INDEX(Points, Match(If(AND(B40>3,B40<11),"Top 10", If(AND(B40>10,NOT(B40=""), B40<26),"Top 25", If(B40="-","Missed Cut", If(B40>25,"Made Cut",B40)))),PointNames, 0))} -> -2 | D40: {=2*(SUM(If(Index(Round1, Match(A40,PlayerLeaderboard, 0))=LowRound1, 1, 0), If(Index(Round2, Match(A40,PlayerLeaderboard, 0))=LowRound2, 1, 0), If(Index(Round3, Match(A40,PlayerLeaderboard, 0))=LowRound3, 1, 0), If(Index(Round4, Match(A40,PlayerLeaderboard, 0))=LowRound4, 1, 0)))} -> 0
A41: Total Points | C41: =SUM(C37:C40)+SUM(D37:D40) -> 4
...

Sheet Leaderboard
B1: POS | C1: PLAYER | D1: SCORE | E1: R1 | F1: R2 | G1: R3 | H1: R4 | I1: TOT | M1: Low Round 1 | N1: Low Round 2 | O1: Low Round 3 | P1: Low Round 4
B2: 1 | C2: Rory McIlroy | D2: -11 | E2: 72 | F2: 66 | G2: 66 | H2: 73 | I2: 277 | M2: =int(MINIFS(Round1, Round1, ">59")) -> 65 | N2: =int(MINIFS(Round2, Round2, ">59")) -> 66 | O2: =int(MINIFS(Round3, Round3, ">59")) -> 66 | P2: =int(MINIFS(Round4, Round4, ">59")) -> 66
B3: 2 | C3: Justin Rose | D3: -11 | E3: 65 | F3: 71 | G3: 75 | H3: 66 | I3: 277
B4: 3 | C4: Patrick Reed | D4: -9 | E4: 71 | F4: 70 | G4: 69 | H4: 69 | I4: 279
B5: 4 | C5: Scottie Scheffler | D5: -8 | E5: 68 | F5: 71 | G5: 72 | H5: 69 | I5: 280
B6: T5 | C6: Sungjae Im | D6: -7 | E6: 71 | F6: 70 | G6: 71 | H6: 69 | I6: 281
B7: T5 | C7: Bryson DeChambeau | D7: -7 | E7: 69 | F7: 68 | G7: 69 | H7: 75 | I7: 281
B8: 7 | C8: Ludvig Åberg | D8: -6 | E8: 68 | F8: 73 | G8: 69 | H8: 72 | I8: 282
B9: T8 | C9: Zach Johnson | D9: -5 | E9: 72 | F9: 74 | G9: 66 | H9: 71 | I9: 283
B10: T8 | C10: Xander Schauffele | D10: -5 | E10: 73 | F10: 69 | G10: 70 | H10: 71 | I10: 283
B11: T8 | C11: Jason Day | D11: -5 | E11: 70 | F11: 70 | G11: 71 | H11: 72 | I11: 283
B12: T8 | C12: Corey Conners | D12: -5 | E12: 68 | F12: 70 | G12: 70 | H12: 75 | I12: 283
B13: T12 | C13: Harris English | D13: -4 | E13: 70 | F13: 73 | G13: 73 | H13: 68 | I13: 284
B14: T12 | C14: Max Homa | D14: -4 | E14: 74 | F14: 70 | G14: 69 | H14: 71 | I14: 284
B15: T14 | C15: Bubba Watson | D15: -3 | E15: 71 | F15: 72 | G15: 74 | H15: 68 | I15: 285
B16: T14 | C16: Jon Rahm | D16: -3 | E16: 75 | F16: 71 | G16: 70 | H16: 69 | I16: 285
B17: T14 | C17: Jordan Spieth | D17: -3 | E17: 73 | F17: 73 | G17: 69 | H17: 70 | I17: 285
B18: T14 | C18: Tom Hoge | D18: -3 | E18: 72 | F18: 72 | G18: 70 | H18: 71 | I18: 285
B19: T14 | C19: Tyrrell Hatton | D19: -3 | E19: 69 | F19: 70 | G19: 75 | H19: 71 | I19: 285
B20: T14 | C20: Matt McCarty | D20: -3 | E20: 71 | F20: 68 | G20: 75 | H20: 71 | I20: 285
... B29: T27 | C29: Michael Kim | D29: -1 | E29: 71 | F29: 71 | G29: 74 | H29: 71 | I29: 287
B30: T29 | C30: Denny McCarthy | D30: E | E30: 71 | F30: 75 | G30: 71 | H30: 71 | I30: 288
B31: T29 | C31: Sahith Theegala | D31: E | E31: 72 | F31: 72 | G31: 73 | H31: 71 | I31: 288
B32: T29 | C32: Joaquín Niemann | D32: E | E32: 72 | F32: 74 | G32: 70 | H32: 72 | I32: 288
B33: T32 | C33: Brian Campbell | D33: +1 | E33: 72 | F33: 73 | G33: 76 | H33: 68 | I33: 289
B34: T32 | C34: Maverick McNealy | D34: +1 | E34: 72 | F34: 73 | G34: 71 | H34: 73 | I34: 289
B35: T32 | C35: Max Greyserman | D35: +1 | E35: 71 | F35: 75 | G35: 69 | H35: 74 | I35: 289
B36: T32 | C36: Rasmus Højgaard | D36: +1 | E36: 73 | F36: 67 | G36: 75 | H36: 74 | I36: 289
B37: T36 | C37: Justin Thomas | D37: +2 | E37: 73 | F37: 71 | G37: 76 | H37: 70 | I37: 290
B38: T36 | C38: Patrick Cantlay | D38: +2 | E38: 74 | F38: 72 | G38: 73 | H38: 71 | I38: 290
B39: T36 | C39: Brian Harman | D39: +2 | E39: 71 | F39: 71 | G39: 77 | H39: 71 | I39: 290
B40: T36 | C40: Charl Schwartzel | D40: +2 | E40: 74 | F40: 72 | G40: 72 | H40: 72 | I40: 290
B41: T40 | C41: Nick Taylor | D41: +3 | E41: 73 | F41: 71 | G41: 74 | H41: 73 | I41: 291
... B49: T46 | C49: Davis Thompson | D49: +5 | E49: 71 | F49: 73 | G49: 70 | H49: 79 | I49: 293
B50: 49 | C50: Min Woo Lee | D50: +6 | E50: 71 | F50: 72 | G50: 77 | H50: 74 | I50: 294
B51: 50 | C51: J.J. Spaun | D51: +7 | E51: 74 | F51: 72 | G51: 74 | H51: 75 | I51: 295
B52: 51 | C52: Nicolas Echavarria | D52: +8 | E52: 73 | F52: 70 | G52: 69 | H52: 84 | I52: 296
B53: T52 | C53: Stephan Jaeger | D53: +9 | E53: 72 | F53: 74 | G53: 73 | H53: 78 | I53: 297
B54: T52 | C54: Tom Kim | D54: +9 | E54: 73 | F54: 73 | G54: 72 | H54: 79 | I54: 297
B55: - | C55: Russell Henley | D55: CUT | E55: 79 | F55: 68 | G55: -- | H55: -- | I55: 147
...

Sheet Pickem Board
B1: Masters Pool It All Comes Down To Sunday | AX1: @dropdown
B3: Shankapotamus ⛳️ | C3: 9 O'clock on the 9th Green | D3: Better Than Most | E3: Maher | F3: Wish Louis was Playing | G3: Putts n' Stuff | H3: Scottie Style | I3: Back to back to back | J3: And33znutz | K3: Magnolia Lane | L3: Shooter's Turn | M3: It's all in the hips | N3: Member's Bounce | O3: Nova | P3: Vandegriff | Q3: Good Good Good | R3: Kyle Beeler | S3: Faldo & Barker | T3: Kroll's Holes | U3: The Putt Pirates | V3: Bizzle Bone 🦴 | W3: Rob Won | X3: Rob Won Two | Y3: Only Boss That Has Won this Before | Z3: Johnson Wagner | AA3: ParTee Animals | AB3: Hosel Rocket | AC3: Putt Blugs | AD3: Baseball Hacks Only | AE3: Rocky | AF3: <Team Name Here> | AG3: <Team Name Here> | AH3: <Team Name Here> | AI3: <Team Name Here> | AJ3: <Team Name Here> | AK3: <Team Name Here> | AL3: <Team Name Here> | AM3: <Team Name Here> | AN3: <Team Name Here> | AO3: <Team Name Here> | AP3: <Team Name Here> | AQ3: <Team Name Here> | AR3: <Team Name Here> | AS3: <Team Name Here> | AT3: <Team Name Here> | AU3: <Team Name Here> | AV3: <Team Name Here> | AW3: <Team Name Here>
A4: Tier 1 | B4: Rory McIlroy | C4: Scottie Scheffler | D4: Scottie Scheffler | E4: Scottie Scheffler | F4: Collin Morikawa | G4: Collin Morikawa | H4: Scottie Scheffler | I4: Scottie Scheffler | J4: Rory McIlroy | K4: Scottie Scheffler | L4: Rory McIlroy | M4: Ludvig Åberg | N4: Rory McIlroy | O4: Scottie Scheffler | P4: Scottie Scheffler | Q4: Scottie Scheffler | R4: Collin Morikawa | S4: Jon Rahm | T4: Bryson DeChambeau | U4: Xander Schauffele | V4: Collin Morikawa | W4: Xander Schauffele | X4: Ludvig Åberg | Y4: Joaquín Niemann | Z4: Rory McIlroy | AA4: Rory McIlroy | AB4: Rory McIlroy | AC4: Rory McIlroy | AD4: Rory McIlroy | AE4: Rory McIlroy
A5: Tier 2 | B5: Jordan Spieth | C5: Tommy Fleetwood | D5: Viktor Hovland | E5: Brooks Koepka | F5: Shane Lowry | G5: Patrick Cantlay | H5: Shane Lowry | I5: Jordan Spieth | J5: Russell Henley | K5: Brooks Koepka | L5: Shane Lowry | M5: Patrick Cantlay | N5: Tommy Fleetwood | O5: Brooks Koepka | P5: Akshay Bhatia | Q5: Brooks Koepka | R5: Robert MacIntyre | S5: Brooks Koepka | T5: Shane Lowry | U5: Shane Lowry | V5: Viktor Hovland | W5: Viktor Hovland | X5: Brooks Koepka | Y5: Will Zalatoris | Z5: Brooks Koepka | AA5: Brooks Koepka | AB5: Tommy Fleetwood | AC5: Shane Lowry | AD5: Brooks Koepka | AE5: Viktor Hovland
A6: Tier 3 | B6: Sahith Theegala | C6: Sepp Straka | D6: Sam Burns | E6: Sergio Garcia | F6: Justin Rose | G6: Dustin Johnson | H6: Sergio Garcia | I6: Maverick McNealy | J6: Tony Finau | K6: Corey Conners | L6: Maverick McNealy | M6: Patrick Reed | N6: Corey Conners | O6: Sam Burns | P6: Billy Horschel | Q6: Tony Finau | R6: Corey Conners | S6: Wyndham Clark | T6: Keegan Bradley | U6: Jason Day | V6: Justin Rose | W6: Jason Day | X6: Sahith Theegala | Y6: Tony Finau | Z6: Justin Rose | AA6: Sergio Garcia | AB6: Sepp Straka | AC6: Maverick McNealy | AD6: Sepp Straka | AE6: Justin Rose
A7: Tier 4 | B7: Cam Davis | C7: Thomas Detry | D7: Cameron Young | E7: Danny Willett | F7: Michael Kim | G7: Cameron Young | H7: Denny McCarthy | I7: Cameron Young | J7: J.T. Poston | K7: Denny McCarthy | L7: Nicolai Højgaard | M7: Cameron Young | N7: Nick Taylor | O7: Max Homa | P7: Cameron Young | Q7: Matt Mccarty | R7: Lucas Glover | S7: Cameron Young | T7: Lucas Glover | U7: J.T. Poston | V7: Max Homa | W7: Max Homa | X7: Cam Davis | Y7: Nicolai Højgaard | Z7: Nicolai Højgaard | AA7: Michael Kim | AB7: Lucas Glover | AC7: Stephan Jaeger | AD7: Denny McCarthy | AE7: Max Homa
A8: Payments: | B8: Paid | C8: Paid | D8: Paid | E8: Paid | F8: Paid | G8: Paid | H8: Paid | I8: Paid | J8: Paid | K8: Paid | L8: Paid | M8: Paid | N8: Paid | O8: Paid | P8: Paid | Q8: Paid | R8: Paid | S8: Paid | T8: Paid | U8: Paid | V8: Paid | W8: Paid | X8: Paid | Y8: Paid | Z8: Paid | AA8: Paid | AB8: Paid | AC8: Paid | AD8: Paid | AE8: Paid
A9: Name | B9: Brett Dutcher | C9: Nate Feldpausch | D9: Dave Phillips | E9: John Maher | F9: Jake Wester | G9: Nick Ranns | H9: John Sinacola | I9: Troy | J9: Andy Semanson | K9: Steve Wester | L9: James Dutcher | M9: Duane Brown | N9: Patrick Doyle | O9: Joe N | P9: Aaron Vandegriff | Q9: Kyle B. | R9: Kyle B. | S9: Nick W | T9: Nick K | U9: Evan Timm | V9: Mike Bielski | W9: Boss Team 1 | X9: Boss Team 2 | Y9: Becca | Z9: Mitch | AA9: John L. | AB9: Weasel | AC9: OB | AD9: Ganci | AE9: Rocky | AF9: <Your Name Here> | AG9: <Your Name Here> | AH9: <Your Name Here> | AI9: <Your Name Here> | AJ9: <Your Name Here> | AK9: <Your Name Here> | AL9: <Your Name Here> | AM9: <Your Name Here> | AN9: <Your Name Here> | AO9: <Your Name Here> | AP9: <Your Name Here> | AQ9: <Your Name Here> | AR9: <Your Name Here> | AS9: <Your Name Here> | AT9: <Your Name Here> | AU9: <Your Name Here> | AV9: <Your Name Here> | AW9: <Your Name Here>
A11: ***Draft Board closes by the first Tee time Thursday

Sheet Player Tiers
A1: TIER 1 | B1: TIER 2 | C1: TIER 3 | D1: TIER 4 | G1: Scottie Scheffler | H1: Scottie Scheffler +650 | I1: Scottie Scheffler +450 | J1: =trim(substitute(SUBSTITUTE(SUBSTITUTE(SUBSTITUTE(SUBSTITUTE(SUBSTITUTE(SUBSTITUTE(SUBSTITUTE(SUBSTITUTE(SUBSTITUTE(SUBSTITUTE(I1, "0", ""), "1", ""), "2", ""), "3", ""), "4", ""), "5", ""), "6", ""), "7", ""), "8", ""), "9", ""), "+","")) -> Scottie Scheffler
A2: Bryson DeChambeau | B2: Akshay Bhatia | C2: Aaron Rai | D2: Adam Schenk | G2: Rory McIlroy | H2: Rory McIlroy +750 | I2: Rory McIlroy +650 | J2: =trim(substitute(SUBSTITUTE(SUBSTITUTE(SUBSTITUTE(SUBSTITUTE(SUBSTITUTE(SUBSTITUTE(SUBSTITUTE(SUBSTITUTE(SUBSTITUTE(SUBSTITUTE(I2, "0", ""), "1", ""), "2", ""), "3", ""), "4", ""), "5", ""), "6", ""), "7", ""), "8", ""), "9", ""), "+","")) -> Rory McIlroy
A3: Collin Morikawa | B3: Brooks Koepka | C3: Adam Scott | D3: Angel Cabrera | G3: Jon Rahm | H3: Jon Rahm +800 | I3: Jon Rahm +1400 | J3: =trim(substitute(SUBSTITUTE(SUBSTITUTE(SUBSTITUTE(SUBSTITUTE(SUBSTITUTE(SUBSTITUTE(SUBSTITUTE(SUBSTITUTE(SUBSTITUTE(SUBSTITUTE(I3, "0", ""), "1", ""), "2", ""), "3", ""), "4", ""), "5", ""), "6", ""), "7", ""), "8", ""), "9", ""), "+","")) -> Jon Rahm
A4: Hideki Matsuyama | B4: Cameron Smith | C4: Billy Horschel | D4: Austin Eckroat | G4: Cameron Smith | H4: Cameron Smith +1400 | I4: Ludvig Åberg +1600 | J4: =trim(substitute(SUBSTITUTE(SUBSTITUTE(SUBSTITUTE(SUBSTITUTE(SUBSTITUTE(SUBSTITUTE(SUBSTITUTE(SUBSTITUTE(SUBSTITUTE(SUBSTITUTE(I4, "0", ""), "1", ""), "2", ""), "3", ""), "4", ""), "5", ""), "6", ""), "7", ""), "8", ""), "9", ""), "+","")) -> Ludvig Åberg
A5: Joaquín Niemann | B5: Jordan Spieth | C5: Brian Harman | D5: Bernhard Langer | G5: Jordan Spieth | H5: Jordan Spieth +1400 | I5: Collin Morikawa +1600 | J5: =trim(substitute(SUBSTITUTE(SUBSTITUTE(SUBSTITUTE(SUBSTITUTE(SUBSTITUTE(SUBSTITUTE(SUBSTITUTE(SUBSTITUTE(SUBSTITUTE(SUBSTITUTE(I5, "0", ""), "1", ""), "2", ""), "3", ""), "4", ""), "5", ""), "6", ""), "7", ""), "8", ""), "9", ""), "+","")) -> Collin Morikawa
A6: Jon Rahm | B6: Min Woo Lee | C6: Byeong Hun An | D6: Brian Campbell | G6: Justin Thomas | H6: Justin Thomas +1500 | I6: Xander Schauffele +1800 | J6: =trim(substitute(SUBSTITUTE(SUBSTITUTE(SUBSTITUTE(SUBSTITUTE(SUBSTITUTE(SUBSTITUTE(SUBSTITUTE(SUBSTITUTE(SUBSTITUTE(SUBSTITUTE(I6, "0", ""), "1", ""), "2", ""), "3", ""), "4", ""), "5", ""), "6", ""), "7", ""), "8", ""), "9", ""), "+","")) -> Xander Schauffele
A7: Justin Thomas | B7: Patrick Cantlay | C7: Corey Conners | D7: Bubba Watson | G7: Will Zalatoris | H7: Will Zalatoris +1600 | I7: Bryson DeChambeau +2000 | J7: =trim(substitute(SUBSTITUTE(SUBSTITUTE(SUBSTITUTE(SUBSTITUTE(SUBSTITUTE(SUBSTITUTE(SUBSTITUTE(SUBSTITUTE(SUBSTITUTE(SUBSTITUTE(I7, "0", ""), "1", ""), "2", ""), "3", ""), "4", ""), "5", ""), "6", ""), "7", ""), "8", ""), "9", ""), "+","")) -> Bryson DeChambeau
A8: Ludvig Åberg | B8: Robert MacIntyre | C8: Daniel Berger | D8: Cam Davis | G8: Collin Morikawa | H8: Collin Morikawa +1600 | I8: Justin Thomas +2200 | J8: =trim(substitute(SUBSTITUTE(SUBSTITUTE(SUBSTITUTE(SUBSTITUTE(SUBSTITUTE(SUBSTITUTE(SUBSTITUTE(SUBSTITUTE(SUBSTITUTE(SUBSTITUTE(I8, "0", ""), "1", ""), "2", ""), "3", ""), "4", ""), "5", ""), "6", ""), "7", ""), "8", ""), "9", ""), "+","")) -> Justin Thomas
A9: Rory McIlroy | B9: Russell Henley | C9: Davis Thompson | D9: Cameron Young | G9: Max Homa | H9: Max Homa +1600 | I9: Joaquin Niemann +2800 | J9: =trim(substitute(SUBSTITUTE(SUBSTITUTE(SUBSTITUTE(SUBSTITUTE(SUBSTITUTE(SUBSTITUTE(SUBSTITUTE(SUBSTITUTE(SUBSTITUTE(SUBSTITUTE(I9, "0", ""), "1", ""), "2", ""), "3", ""), "4", ""), "5", ""), "6", ""), "7", ""), "8", ""), "9", ""), "+","")) -> Joaquin Niemann
A10: Scottie Scheffler | B10: Shane Lowry | C10: Dustin Johnson | D10: Charl Schwartzel | G10: Xander Schauffele | H10: Xander Schauffele +2000 | I10: Hideki Matsuyama +2800 | J10: =trim(substitute(SUBSTITUTE(SUBSTITUTE(SUBSTITUTE(SUBSTITUTE(SUBSTITUTE(SUBSTITUTE(SUBSTITUTE(SUBSTITUTE(SUBSTITUTE(SUBSTITUTE(I10, "0", ""), "1", ""), "2", ""), "3", ""), "4", ""), "5", ""), "6", ""), "7", ""), "8", ""), "9", ""), "+","")) -> Hideki Matsuyama
A11: Xander Schauffele | B11: Tommy Fleetwood | C11: J. J. Spaun | D11: Chris Kirk | G11: Patrick Cantlay | H11: Patrick Cantlay +2000 | I11: Brooks Koepka +3000 | J11: =trim(substitute(SUBSTITUTE(SUBSTITUTE(SUBSTITUTE(SUBSTITUTE(SUBSTITUTE(SUBSTITUTE(SUBSTITUTE(SUBSTITUTE(SUBSTITUTE(SUBSTITUTE(I11, "0", ""), "1", ""), "2", ""), "3", ""), "4", ""), "5", ""), "6", ""), "7", ""), "8", ""), "9", ""), "+","")) -> Brooks Koepka
B12: Tyrrell Hatton | C12: Jason Day | D12: Christiaan Bezuidenhout | G12: Sam Burns | H12: Sam Burns +2500 | I12: Jordan Spieth +3300 | J12: =trim(substitute(SUBSTITUTE(SUBSTITUTE(SUBSTITUTE(SUBSTITUTE(SUBSTITUTE(SUBSTITUTE(SUBSTITUTE(SUBSTITUTE(SUBSTITUTE(SUBSTITUTE(I12, "0", ""), "1", ""), "2", ""), "3", ""), "4", ""), "5", ""), "6", ""), "7", ""), "8", ""), "9", ""), "+","")) -> Jordan Spieth
B13: Viktor Hovland | C13: Justin Rose | D13: Danny Willett | G13: Jason Day | H13: Jason Day +2500 | I13: Tommy Fleetwood +3500 | J13: =trim(substitute(SUBSTITUTE(SUBSTITUTE(SUBSTITUTE(SUBSTITUTE(SUBSTITUTE(SUBSTITUTE(SUBSTITUTE(SUBSTITUTE(SUBSTITUTE(SUBSTITUTE(I13, "0", ""), "1", ""), "2", ""), "3", ""), "4", ""), "5", ""), "6", ""), "7", ""), "8", ""), "9", ""), "+","")) -> Tommy Fleetwood
B14: Will Zalatoris | C14: Keegan Bradley | D14: Davis Riley | G14: Tony Finau | H14: Tony Finau +2800 | I14: Shane Lowry +3500 | J14: =trim(substitute(SUBSTITUTE(SUBSTITUTE(SUBSTITUTE(SUBSTITUTE(SUBSTITUTE(SUBSTITUTE(SUBSTITUTE(SUBSTITUTE(SUBSTITUTE(SUBSTITUTE(I14, "0", ""), "1", ""), "2", ""), "3", ""), "4", ""), "5", ""), "6", ""), "7", ""), "8", ""), "9", ""), "+","")) -> Shane Lowry
C15: Matt Fitzpatrick | D15: Denny McCarthy | G15: Sungjae Im | H15: Sungjae Im +2800 | I15: Viktor Hovland +3500 | J15: =trim(substitute(SUBSTITUTE(SUBSTITUTE(SUBSTITUTE(SUBSTITUTE(SUBSTITUTE(SUBSTITUTE(SUBSTITUTE(SUBSTITUTE(SUBSTITUTE(SUBSTITUTE(I15, "0", ""), "1", ""), "2", ""), "3", ""), "4", ""), "5", ""), "6", ""), "7", ""), "8", ""), "9", ""), "+","")) -> Viktor Hovland
C16: Maverick McNealy | D16: Evan Beck | G16: Dustin Johnson | H16: Dustin Johnson +2800 | I16: Patrick Cantlay +3500 | J16: =trim(substitute(SUBSTITUTE(SUBSTITUTE(SUBSTITUTE(SUBSTITUTE(SUBSTITUTE(SUBSTITUTE(SUBSTITUTE(SUBSTITUTE(SUBSTITUTE(SUBSTITUTE(I16, "0", ""), "1", ""), "2", ""), "3", ""), "4", ""), "5", ""), "6", ""), "7", ""), "8", ""), "9", ""), "+","")) -> Patrick Cantlay
C17: Patrick Reed | D17: Fred Couples | G17: Viktor Hovland | H17: Viktor Hovland +2800 | I17: Tyrrell Hatton +4000 | J17: =trim(substitute(SUBSTITUTE(SUBSTITUTE(SUBSTITUTE(SUBSTITUTE(SUBSTITUTE(SUBSTITUTE(SUBSTITUTE(SUBSTITUTE(SUBSTITUTE(SUBSTITUTE(I17, "0", ""), "1", ""), "2", ""), "3", ""), "4", ""), "5", ""), "6", ""), "7", ""), "8", ""), "9", ""), "+","")) -> Tyrrell Hatton
C18: Phil Mickelson | D18: Harris English | G18: Cameron Young | H18: Cameron Young +3000 | I18: Robert MacIntyre +5500 | J18: =trim(substitute(SUBSTITUTE(SUBSTITUTE(SUBSTITUTE(SUBSTITUTE(SUBSTITUTE(SUBSTITUTE(SUBSTITUTE(SUBSTITUTE(SUBSTITUTE(SUBSTITUTE(I18, "0", ""), "1", ""), "2", ""), "3", ""), "4", ""), "5", ""), "6", ""), "7", ""), "8", ""), "9", ""), "+","")) -> Robert MacIntyre
C19: Sahith Theegala | D19: Hiroshi Tai | G19: Brooks Koepka | H19: Brooks Koepka +3000 | I19: Russell Henley +5500 | J19: =trim(substitute(SUBSTITUTE(SUBSTITUTE(SUBSTITUTE(SUBSTITUTE(SUBSTITUTE(SUBSTITUTE(SUBSTITUTE(SUBSTITUTE(SUBSTITUTE(SUBSTITUTE(I19, "0", ""), "1", ""), "2", ""), "3", ""), "4", ""), "5", ""), "6", ""), "7", ""), "8", ""), "9", ""), "+","")) -> Russell Henley
C20: Sam Burns | D20: J.T. Poston | G20: Tom Kim | H20: Tom Kim +3300 | I20: Min Woo Lee +5500 | J20: =trim(substitute(SUBSTITUTE(SUBSTITUTE(SUBSTITUTE(SUBSTITUTE(SUBSTITUTE(SUBSTITUTE(SUBSTITUTE(SUBSTITUTE(SUBSTITUTE(SUBSTITUTE(I20, "0", ""), "1", ""), "2", ""), "3", ""), "4", ""), "5", ""), "6", ""), "7", ""), "8", ""), "9", ""), "+","")) -> Min Woo Lee
C21: Sepp Straka | D21: Jhonattan Vegas | G21: Hideki Matsuyama | H21: Hideki Matsuyama +3500 | I21: Will Zalatoris +5500 | J21: =trim(substitute(SUBSTITUTE(SUBSTITUTE(SUBSTITUTE(SUBSTITUTE(SUBSTITUTE(SUBSTITUTE(SUBSTITUTE(SUBSTITUTE(SUBSTITUTE(SUBSTITUTE(I21, "0", ""), "1", ""), "2", ""), "3", ""), "4", ""), "5", ""), "6", ""), "7", ""), "8", ""), "9", ""), "+","")) -> Will Zalatoris
C22: Sergio Garcia | D22: Joe Highsmith | G22: Matthew Fitzpatrick | H22: Matthew Fitzpatrick +3500 | I22: Cameron Smith +6000 | J22: =trim(substitute(SUBSTITUTE(SUBSTITUTE(SUBSTITUTE(SUBSTITUTE(SUBSTITUTE(SUBSTITUTE(SUBSTITUTE(SUBSTITUTE(SUBSTITUTE(SUBSTITUTE(I22, "0", ""), "1", ""), "2", ""), "3", ""), "4", ""), "5", ""), "6", ""), "7", ""), "8", ""), "9", ""), "+","")) -> Cameron Smith
C23: Sungjae Im | D23: Jose Luis Ballester | G23: Joaquin Niemann | H23: Joaquin Niemann +4000 | I23: Akshay Bhatia +6500 | J23: =trim(substitute(SUBSTITUTE(SUBSTITUTE(SUBSTITUTE(SUBSTITUTE(SUBSTITUTE(SUBSTITUTE(SUBSTITUTE(SUBSTITUTE(SUBSTITUTE(SUBSTITUTE(I23, "0", ""), "1", ""), "2", ""), "3", ""), "4", ""), "5", ""), "6", ""), "7", ""), "8", ""), "9", ""), "+","")) -> Akshay Bhatia
C24: Taylor Pendrith | D24: Jose Maria Olazábal | G24: Shane Lowry | H24: Shane Lowry +4500 | I24: Corey Conners +7500 | J24: =trim(substitute(SUBSTITUTE(SUBSTITUTE(SUBSTITUTE(SUBSTITUTE(SUBSTITUTE(SUBSTITUTE(SUBSTITUTE(SUBSTITUTE(SUBSTITUTE(SUBSTITUTE(I24, "0", ""), "1", ""), "2", ""), "3", ""), "4", ""), "5", ""), "6", ""), "7", ""), "8", ""), "9", ""), "+","")) -> Corey Conners
C25: Tom Kim | D25: Justin Hastings | G25: Keith Mitchell | H25: Keith Mitchell +5000 | I25: Tony Finau +7500 | J25: =trim(substitute(SUBSTITUTE(SUBSTITUTE(SUBSTITUTE(SUBSTITUTE(SUBSTITUTE(SUBSTITUTE(SUBSTITUTE(SUBSTITUTE(SUBSTITUTE(SUBSTITUTE(I25, "0", ""), "1", ""), "2", ""), "3", ""), "4", ""), "5", ""), "6", ""), "7", ""), "8", ""), "9", ""), "+","")) -> Tony Finau
C26: Tony Finau | D26: Kevin Yu | G26: Tyrrell Hatton | H26: Tyrrell Hatton +5500 | I26: Jason Day +8000 | J26: =trim(substitute(SUBSTITUTE(SUBSTITUTE(SUBSTITUTE(SUBSTITUTE(SUBSTITUTE(SUBSTITUTE(SUBSTITUTE(SUBSTITUTE(SUBSTITUTE(SUBSTITUTE(I26, "0", ""), "1", ""), "2", ""), "3", ""), "4", ""), "5", ""), "6", ""), "7", ""), "8", ""), "9", ""), "+","")) -> Jason Day
C27: Wyndham Clark | D27: Laurie Canter | G27: Tiger Woods | H27: Tiger Woods +6000 | I27: Sepp Straka +8000 | J27: =trim(substitute(SUBSTITUTE(SUBSTITUTE(SUBSTITUTE(SUBSTITUTE(SUBSTITUTE(SUBSTITUTE(SUBSTITUTE(SUBSTITUTE(SUBSTITUTE(SUBSTITUTE(I27, "0", ""), "1", ""), "2", ""), "3", ""), "4", ""), "5", ""), "6", ""), "7", ""), "8", ""), "9", ""), "+","")) -> Sepp Straka
D28: Lucas Glover | G28: Tommy Fleetwood | H28: Tommy Fleetwood +6000 | I28: Wyndham Clark +8000 | J28: =trim(substitute(SUBSTITUTE(SUBSTITUTE(SUBSTITUTE(SUBSTITUTE(SUBSTITUTE(SUBSTITUTE(SUBSTITUTE(SUBSTITUTE(SUBSTITUTE(SUBSTITUTE(I28, "0", ""), "1", ""), "2", ""), "3", ""), "4", ""), "5", ""), "6", ""), "7", ""), "8", ""), "9", ""), "+","")) -> Wyndham Clark
D29: Matt Mccarty | G29: Bryson DeChambeau | H29: Bryson DeChambeau +6500 | I29: Dustin Johnson +8000 | J29: =trim(substitute(SUBSTITUTE(SUBSTITUTE(SUBSTITUTE(SUBSTITUTE(SUBSTITUTE(SUBSTITUTE(SUBSTITUTE(SUBSTITUTE(SUBSTITUTE(SUBSTITUTE(I29, "0", ""), "1", ""), "2", ""), "3", ""), "4", ""), "5", ""), "6", ""), "7", ""), "8", ""), "9", ""), "+","")) -> Dustin Johnson
D30: Matthieu Pavon | G30: Justin Rose | H30: Justin Rose +7000 | I30: Sergio Garcia +8000 | J30: =trim(substitute(SUBSTITUTE(SUBSTITUTE(SUBSTITUTE(SUBSTITUTE(SUBSTITUTE(SUBSTITUTE(SUBSTITUTE(SUBSTITUTE(SUBSTITUTE(SUBSTITUTE(I30, "0", ""), "1", ""), "2", ""), "3", ""), "4", ""), "5", ""), "6", ""), "7", ""), "8", ""), "9", ""), "+","")) -> Sergio Garcia
D31: Max Greyserman | G31: Corey Conners | H31: Corey Conners +7500 | I31: Sahith Theegala +9000 | J31: =trim(substitute(SUBSTITUTE(SUBSTITUTE(SUBSTITUTE(SUBSTITUTE(SUBSTITUTE(SUBSTITUTE(SUBSTITUTE(SUBSTITUTE(SUBSTITUTE(SUBSTITUTE(I31, "0", ""), "1", ""), "2", ""), "3", ""), "4", ""), "5", ""), "6", ""), "7", ""), "8", ""), "9", ""), "+","")) -> Sahith Theegala
D32: Max Homa | G32: Louis Oosthuizen | H32: Louis Oosthuizen +7500 | I32: Patrick Reed +9000 | J32: =trim(substitute(SUBSTITUTE(SUBSTITUTE(SUBSTITUTE(SUBSTITUTE(SUBSTITUTE(SUBSTITUTE(SUBSTITUTE(SUBSTITUTE(SUBSTITUTE(SUBSTITUTE(I32, "0", ""), "1", ""), "2", ""), "3", ""), "4", ""), "5", ""), "6", ""), "7", ""), "8", ""), "9", ""), "+","")) -> Patrick Reed
D33: Michael Kim | G33: Patrick Reed | H33: Patrick Reed +8000 | I33: Keegan Bradley +11000 | J33: =trim(substitute(SUBSTITUTE(SUBSTITUTE(SUBSTITUTE(SUBSTITUTE(SUBSTITUTE(SUBSTITUTE(SUBSTITUTE(SUBSTITUTE(SUBSTITUTE(SUBSTITUTE(I33, "0", ""), "1", ""), "2", ""), "3", ""), "4", ""), "5", ""), "6", ""), "7", ""), "8", ""), "9", ""), "+","")) -> Keegan Bradley
D34: Mike Weir | G34: Russell Henley | H34: Russell Henley +8000 | I34: Tom Kim +11000 | J34: =trim(substitute(SUBSTITUTE(SUBSTITUTE(SUBSTITUTE(SUBSTITUTE(SUBSTITUTE(SUBSTITUTE(SUBSTITUTE(SUBSTITUTE(SUBSTITUTE(SUBSTITUTE(I34, "0", ""), "1", ""), "2", ""), "3", ""), "4", ""), "5", ""), "6", ""), "7", ""), "8", ""), "9", ""), "+","")) -> Tom Kim
D35: Nick Dunlap | G35: Sahith Theegala | H35: Sahith Theegala +8000 | I35: Justin Rose +11000 | J35: =trim(substitute(SUBSTITUTE(SUBSTITUTE(SUBSTITUTE(SUBSTITUTE(SUBSTITUTE(SUBSTITUTE(SUBSTITUTE(SUBSTITUTE(SUBSTITUTE(SUBSTITUTE(I35, "0", ""), "1", ""), "2", ""), "3", ""), "4", ""), "5", ""), "6", ""), "7", ""), "8", ""), "9", ""), "+","")) -> Justin Rose
D36: Nick Taylor | G36: Abraham Ancer | H36: Abraham Ancer +8500 | I36: Sungjae Im +11000 | J36: =trim(substitute(SUBSTITUTE(SUBSTITUTE(SUBSTITUTE(SUBSTITUTE(SUBSTITUTE(SUBSTITUTE(SUBSTITUTE(SUBSTITUTE(SUBSTITUTE(SUBSTITUTE(I36, "0", ""), "1", ""), "2", ""), "3", ""), "4", ""), "5", ""), "6", ""), "7", ""), "8", ""), "9", ""), "+","")) -> Sungjae Im
D37: Nicolai Højgaard | G37: Talor Gooch | H37: Talor Gooch +9000 | I37: Brian Harman +11000 | J37: =trim(substitute(SUBSTITUTE(SUBSTITUTE(SUBSTITUTE(SUBSTITUTE(SUBSTITUTE(SUBSTITUTE(SUBSTITUTE(SUBSTITUTE(SUBSTITUTE(SUBSTITUTE(I37, "0", ""), "1", ""), "2", ""), "3", ""), "4", ""), "5", ""), "6", ""), "7", ""), "8", ""), "9", ""), "+","")) -> Brian Harman
D38: Nicolas Echavarria | G38: Si-Woo Kim | H38: Si-Woo Kim +9000 | I38: Daniel Berger +11000 | J38: =trim(substitute(SUBSTITUTE(SUBSTITUTE(SUBSTITUTE(SUBSTITUTE(SUBSTITUTE(SUBSTITUTE(SUBSTITUTE(SUBSTITUTE(SUBSTITUTE(SUBSTITUTE(I38, "0", ""), "1", ""), "2", ""), "3", ""), "4", ""), "5", ""), "6", ""), "7", ""), "8", ""), "9", ""), "+","")) -> Daniel Berger
D39: Noah Kent | G39: Mito Pereira | H39: Mito Pereira +9000 | I39: Matt Fitzpatrick +12000 | J39: =trim(substitute(SUBSTITUTE(SUBSTITUTE(SUBSTITUTE(SUBSTITUTE(SUBSTITUTE(SUBSTITUTE(SUBSTITUTE(SUBSTITUTE(SUBSTITUTE(SUBSTITUTE(I39, "0", ""), "1", ""), "2", ""), "3", ""), "4", ""), "5", ""), "6", ""), "7", ""), "8", ""), "9", ""), "+","")) -> Matt Fitzpatrick
... D48: Zach Johnson | G48: Gary Woodland | H48: Gary Woodland +15000 | I48: J. J. Spaun +15000 | J48: =trim(substitute(SUBSTITUTE(SUBSTITUTE(SUBSTITUTE(SUBSTITUTE(SUBSTITUTE(SUBSTITUTE(SUBSTITUTE(SUBSTITUTE(SUBSTITUTE(SUBSTITUTE(I48, "0", ""), "1", ""), "2", ""), "3", ""), "4", ""), "5", ""), "6", ""), "7", ""), "8", ""), "9", ""), "+","")) -> J. J. Spaun
...

Sheet Payouts
A1: Buy In | B1: 20 | C1: Percent of Pot | D1: Number of Teams (in case of ties)
A3: Number of Entries | B3: =COUNTIF('Pickem Board'!B3:AW3,"<>*<Team Name Here>*") -> 30
A5: Total Pot | B5: =B1*B3 -> 600 | C5: =SUM(C7:C9) -> 1
A7: 1st | B7: =(C7*B5)/D7 -> 420 | C7: 0.7 | D7: 1
A8: 2nd | B8: =(C8*B5)/D8 -> 120 | C8: 0.2 | D8: 1
A9: 3rd | B9: =(C9*B5)/D9 -> 60 | C9: 0.1 | D9: 1
A10: ***Scoring - Refer to Scoring Tab
A13: PAYMENT:
A14: Please use Venmo for payment - @Brett-Dutcher

Sheet Scoring
A1: 1 | B1: 25
A2: 2 | B2: 15
A3: 3 | B3: 12
A4: Top 10 | B4: 8
A5: Top 25 | B5: 5
A6: Made Cut | B6: 3
A7: Missed Cut | B7: -2
A8: Low Round | B8: 2

Sheet Final
A1: POS | C1: PLAYER | D1: SCORE | E1: TODAY | F1: THRU | G1: R1 | H1: R2 | I1: R3 | J1: R4 | K1: TOT
A2: 1 | B2: - | C2: Scottie Scheffler | D2: -12 | E2: -3 | F2: 17 | G2: 69 | H2: 67 | I2: 71 | J2: -- | K2: 207
A3: 2 | B3: 7 | C3: Rory McIlroy | D3: -7 | E3: -8 | F3: F | G3: 73 | H3: 73 | I3: 71 | J3: 64 | K3: 281
A4: T3 | B4: 1 | C4: Shane Lowry | D4: -5 | E4: -3 | F4: F | G4: 73 | H4: 68 | I4: 73 | J4: 69 | K4: 283
A5: T3 | B5: 1 | C5: Cameron Smith | D5: -5 | E5: +1 | F5: 17 | G5: 68 | H5: 74 | I5: 68 | J5: -- | K5: 210
A6: 5 | B6: 4 | C6: Collin Morikawa | D6: -4 | E6: -5 | F6: F | G6: 73 | H6: 70 | I6: 74 | J6: 67 | K6: 284
A7: T6 | B7: 8 | C7: Will Zalatoris | D7: -3 | E7: -5 | F7: F | G7: 71 | H7: 72 | I7: 75 | J7: 67 | K7: 285
A8: T6 | B8: - | C8: Corey Conners | D8: -3 | E8: -2 | F8: F | G8: 70 | H8: 73 | I8: 72 | J8: 70 | K8: 285
A9: T8 | B9: 2 | C9: Justin Thomas | D9: -1 | E9: E | F9: F | G9: 76 | H9: 67 | I9: 72 | J9: 72 | K9: 287
A10: T8 | B10: 5 | C10: Sungjae Im | D10: -1 | E10: +3 | F10: F | G10: 67 | H10: 74 | I10: 71 | J10: 75 | K10: 287
A11: T10 | B11: 4 | C11: Cameron Champ | D11: E | E11: -2 | F11: F | G11: 72 | H11: 75 | I11: 71 | J11: 70 | K11: 288
A12: T10 | B12: 6 | C12: Charl Schwartzel | D12: E | E12: +2 | F12: F | G12: 72 | H12: 69 | I12: 73 | J12: 74 | K12: 288
A13: T12 | B13: 3 | C13: Dustin Johnson | D13: +1 | E13: E | F13: F | G13: 69 | H13: 73 | I13: 75 | J13: 72 | K13: 289
A14: T12 | B14: 4 | C14: Danny Willett | D14: +1 | E14: +1 | F14: F | G14: 69 | H14: 74 | I14: 73 | J14: 73 | K14: 289
A15: T14 | B15: 20 | C15: Kevin Na | D15: +2 | E15: -3 | F15: F | G15: 71 | H15: 71 | I15: 79 | J15: 69 | K15: 290
A16: T14 | B16: 12 | C16: Matt Fitzpatrick | D16: +2 | E16: -2 | F16: F | G16: 71 | H16: 73 | I16: 76 | J16: 70 | K16: 290
A17: T14 | B17: 12 | C17: Min Woo Lee | D17: +2 | E17: -2 | F17: F | G17: 73 | H17: 75 | I17: 72 | J17: 70 | K17: 290
A18: T14 | B18: 4 | C18: Harry Higgs | D18: +2 | E18: -1 | F18: F | G18: 71 | H18: 75 | I18: 73 | J18: 71 | K18: 290
A19: T14 | B19: 4 | C19: Lee Westwood | D19: +2 | E19: -1 | F19: F | G19: 72 | H19: 74 | I19: 73 | J19: 71 | K19: 290
A20: T14 | B20: 4 | C20: Talor Gooch | D20: +2 | E20: -1 | F20: F | G20: 72 | H20: 74 | I20: 73 | J20: 71 | K20: 290
A21: T14 | B21: - | C21: Hideki Matsuyama | D21: +2 | E21: E | F21: F | G21: 72 | H21: 69 | I21: 77 | J21: 72 | K21: 290
A22: T14 | B22: 5 | C22: Jason Kokrak | D22: +2 | E22: +1 | F22: F | G22: 70 | H22: 76 | I22: 71 | J22: 73 | K22: 290
A23: T14 | B23: 5 | C23: Tommy Fleetwood | D23: +2 | E23: +1 | F23: F | G23: 75 | H23: 72 | I23: 70 | J23: 73 | K23: 290
A24: T23 | B24: 13 | C24: Robert MacIntyre | D24: +3 | E24: -3 | F24: F | G24: 73 | H24: 73 | I24: 76 | J24: 69 | K24: 291
A25: T23 | B25: 13 | C25: Harold Varner III | D25: +3 | E25: -3 | F25: F | G25: 71 | H25: 71 | I25: 80 | J25: 69 | K25: 291
A26: T23 | B26: 3 | C26: Sergio Garcia | D26: +3 | E26: -1 | F26: F | G26: 72 | H26: 74 | I26: 74 | J26: 71 | K26: 291
A27: T23 | B27: 5 | C27: J.J. Spaun | D27: +3 | E27: E | F27: F | G27: 74 | H27: 70 | I27: 75 | J27: 72 | K27: 291
A28: T27 | B28: 14 | C28: Jon Rahm | D28: +4 | E28: -3 | F28: F | G28: 74 | H28: 72 | I28: 77 | J28: 69 | K28: 292
A29: T27 | B29: 9 | C29: Seamus Power | D29: +4 | E29: -2 | F29: F | G29: 74 | H29: 74 | I29: 74 | J29: 70 | K29: 292
A30: T27 | B30: 9 | C30: Viktor Hovland | D30: +4 | E30: +1 | F30: F | G30: 72 | H30: 76 | I30: 71 | J30: 73 | K30: 292
A31: T30 | B31: 11 | C31: Russell Henley | D31: +5 | E31: -2 | F31: F | G31: 73 | H31: 74 | I31: 76 | J31: 70 | K31: 293
A32: T30 | B32: 6 | C32: Sepp Straka | D32: +5 | E32: -1 | F32: F | G32: 74 | H32: 72 | I32: 76 | J32: 71 | K32: 293
A33: T30 | B33: 4 | C33: Lucas Glover | D33: +5 | E33: +1 | F33: F | G33: 72 | H33: 76 | I33: 72 | J33: 73 | K33: 293
A34: T30 | B34: 12 | C34: Hudson Swafford | D34: +5 | E34: +2 | F34: F | G34: 77 | H34: 69 | I34: 73 | J34: 74 | K34: 293
A35: T30 | B35: 12 | C35: Marc Leishman | D35: +5 | E35: +2 | F35: F | G35: 73 | H35: 75 | I35: 71 | J35: 74 | K35: 293
A36: T35 | B36: 9 | C36: Joaquin Niemann | D36: +6 | E36: +2 | F36: F | G36: 69 | H36: 74 | I36: 77 | J36: 74 | K36: 294
A37: T35 | B37: 9 | C37: Tony Finau | D37: +6 | E37: +2 | F37: F | G37: 71 | H37: 75 | I37: 74 | J37: 74 | K37: 294
A38: T35 | B38: 9 | C38: Patrick Reed | D38: +6 | E38: +2 | F38: F | G38: 74 | H38: 73 | I38: 73 | J38: 74 | K38: 294
A39: T35 | B39: 21 | C39: Webb Simpson | D39: +6 | E39: +4 | F39: F | G39: 71 | H39: 74 | I39: 73 | J39: 76 | K39: 294
A40: T39 | B40: 6 | C40: Patrick Cantlay | D40: +7 | E40: -1 | F40: F | G40: 70 | H40: 75 | I40: 79 | J40: 71 | K40: 295
...
